Workbook

Sheet Dashboard
B1: =CoName&" · SmartTrader ERP" -> Your Trading Co. · SmartTrader ERP
B2: ="Live business cockpit · Period: "&DAY(D4)&"/"&MONTH(D4)&"/"&YEAR(D4)&" to "&DAY(G4)&"/"&MONTH(G4)&"/"&YEAR(G4) -> Live business cockpit · Period: 1/4/2026 to 11/10/2026
B3: =IF(IsPro,LicStatus&" · lines used: "&"Sales "&COUNTA(Sales!$D$5:$D$3004)&" · Purchases "&COUNTA(Purchases!$D$5:$D$3004)&" · Cash Book "&COUNTA(CashBook!$C$5:$C$3004),LicStatus&" · first 200 lines per register · used: "&"Sales "&COUNTA(Sales!$D$5:$D$3004)&" · Purchases "&COUNTA(Purchases!$D$5:$D$3004)&" · Cash Book "&COUNTA(CashBook!$C$5:$C$3004)&IF(OverFreeLimit," >> LIMIT REACHED: newer lines are not counted - upgrade on the Plans sheet","")) -> FREE PLAN · first 200 lines per register · used: Sales 151 · Purchases 33 · Cash Book 121
B4: From | D4: =FYStart -> 46113 | E4: To | G4: =AsOf -> 46306 | H4: ← overwrite these dates to analyse any period
B6: New Sale | C6: Purchase | D6: Cash Book | E6: Items | F6: Parties | G6: Invoice | H6: Adjust | I6: Reports | J6: Settings | K6: Guide | L6: PRO Plans
B8: SALES (excl. GST) | D8: GROSS PROFIT | F8: NET PROFIT | H8: PURCHASES (excl. GST) | J8: EXPENSES
B9: =SUMIFS(Sales!$L$5:INDEX(Sales!$L$5:$L$3004,TxRows),Sales!$A$5:INDEX(Sales!$A$5:$A$3004,TxRows),">="&DFrom,Sales!$A$5:INDEX(Sales!$A$5:$A$3004,TxRows),"<="&DTo) -> 1288883.1 | D9: =SUMIFS(Sales!$S$5:INDEX(Sales!$S$5:$S$3004,TxRows),Sales!$A$5:INDEX(Sales!$A$5:$A$3004,TxRows),">="&DFrom,Sales!$A$5:INDEX(Sales!$A$5:$A$3004,TxRows),"<="&DTo) -> 291168.19 | F9: =D9-SUMIFS(CashBook!$G$5:INDEX(CashBook!$G$5:$G$3004,TxRows),CashBook!$C$5:INDEX(CashBook!$C$5:$C$3004,TxRows),"Expense",CashBook!$A$5:INDEX(CashBook!$A$5:$A$3004,TxRows),">="&DFrom,CashBook!$A$5:INDEX(CashBook!$A$5:$A$3004,TxRows),"<="&DTo)+SUMIFS(CashBook!$G$5:INDEX(CashBook!$G$5:$G$3004,TxRows),CashBook!$C$5:INDEX(CashBook!$C$5:$C$3004,TxRows),"Other Income",CashBook!$A$5:INDEX(CashBook!$A$5:$A$3004,TxRows),">="&DFrom,CashBook!$A$5:INDEX(CashBook!$A$5:$A$3004,TxRows),"<="&DTo)+SUMIFS(Adjustments!$G$5:$G$504,Adjustments!$A$5:$A$504,">="&DFrom,Adjustments!$A$5:$A$504,"<="&DTo) -> 56840.39 | H9: =SUMIFS(Purchases!$K$5:INDEX(Purchases!$K$5:$K$3004,TxRows),Purchases!$A$5:INDEX(Purchases!$A$5:$A$3004,TxRows),">="&DFrom,Purchases!$A$5:INDEX(Purchases!$A$5:$A$3004,TxRows),"<="&DTo) -> 1074712 | J9: =SUMIFS(CashBook!$G$5:INDEX(CashBook!$G$5:$G$3004,TxRows),CashBook!$C$5:INDEX(CashBook!$C$5:$C$3004,TxRows),"Expense",CashBook!$A$5:INDEX(CashBook!$A$5:$A$3004,TxRows),">="&DFrom,CashBook!$A$5:INDEX(CashBook!$A$5:$A$3004,TxRows),"<="&DTo) -> 233298
B11: GP MARGIN | D11: RECEIVABLES (owed to you) | F11: PAYABLES (you owe) | H11: STOCK VALUE (at cost) | J11: NET GST PAYABLE
B12: =IF(B9=0,0,D9/B9) -> 0.22590736 | D12: =SUMIF(Parties!$N$5:$N$304,">0") -> 67030.63 | F12: =-SUMIF(Parties!$N$5:$N$304,"<0") -> 37223.86 | H12: =SUM(Items!$Q$5:$Q$504) -> 478767.28 | J12: =SUMIFS(Sales!$N$5:INDEX(Sales!$N$5:$N$3004,TxRows),Sales!$A$5:INDEX(Sales!$A$5:$A$3004,TxRows),">="&DFrom,Sales!$A$5:INDEX(Sales!$A$5:$A$3004,TxRows),"<="&DTo)+SUMIFS(Sales!$O$5:INDEX(Sales!$O$5:$O$3004,TxRows),Sales!$A$5:INDEX(Sales!$A$5:$A$3004,TxRows),">="&DFrom,Sales!$A$5:INDEX(Sales!$A$5:$A$3004,TxRows),"<="&DTo)+SUMIFS(Sales!$P$5:INDEX(Sales!$P$5:$P$3004,TxRows),Sales!$A$5:INDEX(Sales!$A$5:$A$3004,TxRows),">="&DFrom,Sales!$A$5:INDEX(Sales!$A$5:$A$3004,TxRows),"<="&DTo)-SUMIFS(Purchases!$M$5:INDEX(Purchases!$M$5:$M$3004,TxRows),Purchases!$A$5:INDEX(Purchases!$A$5:$A$3004,TxRows),">="&DFrom,Purchases!$A$5:INDEX(Purchases!$A$5:$A$3004,TxRows),"<="&DTo)-SUMIFS(Purchases!$N$5:INDEX(Purchases!$N$5:$N$3004,TxRows),Purchases!$A$5:INDEX(Purchases!$A$5:$A$3004,TxRows),">="&DFrom,Purchases!$A$5:INDEX(Purchases!$A$5:$A$3004,TxRows),"<="&DTo)-SUMIFS(Purchases!$O$5:INDEX(Purchases!$O$5:$O$3004,TxRows),Purchases!$A$5:INDEX(Purchases!$A$5:$A$3004,TxRows),">="&DFrom,Purchases!$A$5:INDEX(Purchases!$A$5:$A$3004,TxRows),"<="&DTo) -> 23042.26
B14: ITEMS TO REORDER | D14: DEAD-STOCK ITEMS | F14: OVERDUE CUSTOMERS | H14: PENDING DELIVERIES (lines) | J14: NEXT INVOICE No.
B15: =COUNTIF(Items!$R$5:$R$504,"REORDER")+COUNTIF(Items!$R$5:$R$504,"OUT OF STOCK")+COUNTIF(Items!$R$5:$R$504,"NEGATIVE") -> 1 | D15: =COUNTIF(Items!$R$5:$R$504,"DEAD STOCK") -> 0 | F15: =COUNTIF(Parties!$S$5:$S$304,"OVERDUE")+COUNTIF(Parties!$S$5:$S$304,"OVER LIMIT") -> 0 | H15: =COUNTIFS(Sales!$I$5:INDEX(Sales!$I$5:$I$3004,TxRows),"Pending")+COUNTIFS(Sales!$I$5:INDEX(Sales!$I$5:$I$3004,TxRows),"Packed") -> 2 | J15: =InvPrefix&TEXT(MAX(Sales!$W$5:INDEX(Sales!$W$5:$W$3004,TxRows))+1,"0000") -> INV-0128
B18: CASH & BANK BALANCES (as of 'To' date) | I18: TOP 10 ITEMS BY SALES (all time)
B19: Account | D19: Opening | E19: In | F19: Out | G19: Balance | I19: # | J19: Item | L19: Sales (₹) | M19: Stock | N19: Status
B20: =IF(Settings!$A$18="","",Settings!$A$18) -> Cash | D20: =IF(B20="","",N(Settings!$B$18)) -> 50000 | E20: =IF(B20="","",SUMIFS(CashBook!$I$5:INDEX(CashBook!$I$5:$I$3004,TxRows),CashBook!$F$5:INDEX(CashBook!$F$5:$F$3004,TxRows),B20,CashBook!$A$5:INDEX(CashBook!$A$5:$A$3004,TxRows),"<="&DTo)+SUMIFS(Sales!$X$5:INDEX(Sales!$X$5:$X$3004,TxRows),Sales!$H$5:INDEX(Sales!$H$5:$H$3004,TxRows),B20,Sales!$A$5:INDEX(Sales!$A$5:$A$3004,TxRows),"<="&DTo)) -> 539651.8 | F20: =IF(B20="","",SUMIFS(CashBook!$J$5:INDEX(CashBook!$J$5:$J$3004,TxRows),CashBook!$F$5:INDEX(CashBook!$F$5:$F$3004,TxRows),B20,CashBook!$A$5:INDEX(CashBook!$A$5:$A$3004,TxRows),"<="&DTo)+SUMIFS(Purchases!$S$5:INDEX(Purchases!$S$5:$S$3004,TxRows),Purchases!$H$5:INDEX(Purchases!$H$5:$H$3004,TxRows),B20,Purchases!$A$5:INDEX(Purchases!$A$5:$A$3004,TxRows),"<="&DTo)) -> 515325 | G20: =IF(B20="","",D20+E20-F20) -> 74326.8 | I20: 1 | J20: =IFERROR(IF(INDEX(Items!$U$5:$U$504,MATCH(LARGE(Items!$Z$5:$Z$504,1),Items!$Z$5:$Z$504,0))=0,"",INDEX(Items!$A$5:$A$504,MATCH(LARGE(Items!$Z$5:$Z$504,1),Items!$Z$5:$Z$504,0))),"") -> Refined Oil 15L | L20: =IF(J20="","",INDEX(Items!$U$5:$U$504,MATCH(LARGE(Items!$Z$5:$Z$504,1),Items!$Z$5:$Z$504,0))) -> 226435.2 | M20: =IF(J20="","",INDEX(Items!$O$5:$O$504,MATCH(LARGE(Items!$Z$5:$Z$504,1),Items!$Z$5:$Z$504,0))) -> 11 | N20: =IF(J20="","",INDEX(Items!$R$5:$R$504,MATCH(LARGE(Items!$Z$5:$Z$504,1),Items!$Z$5:$Z$504,0))) -> OK
B21: =IF(Settings!$A$19="","",Settings!$A$19) -> Bank | D21: =IF(B21="","",N(Settings!$B$19)) -> 250000 | E21: =IF(B21="","",SUMIFS(CashBook!$I$5:INDEX(CashBook!$I$5:$I$3004,TxRows),CashBook!$F$5:INDEX(CashBook!$F$5:$F$3004,TxRows),B21,CashBook!$A$5:INDEX(CashBook!$A$5:$A$3004,TxRows),"<="&DTo)+SUMIFS(Sales!$X$5:INDEX(Sales!$X$5:$X$3004,TxRows),Sales!$H$5:INDEX(Sales!$H$5:$H$3004,TxRows),B21,Sales!$A$5:INDEX(Sales!$A$5:$A$3004,TxRows),"<="&DTo)) -> 1164653.8 | F21: =IF(B21="","",SUMIFS(CashBook!$J$5:INDEX(CashBook!$J$5:$J$3004,TxRows),CashBook!$F$5:INDEX(CashBook!$F$5:$F$3004,TxRows),B21,CashBook!$A$5:INDEX(CashBook!$A$5:$A$3004,TxRows),"<="&DTo)+SUMIFS(Purchases!$S$5:INDEX(Purchases!$S$5:$S$3004,TxRows),Purchases!$H$5:INDEX(Purchases!$H$5:$H$3004,TxRows),B21,Purchases!$A$5:INDEX(Purchases!$A$5:$A$3004,TxRows),"<="&DTo)) -> 1340591.2 | G21: =IF(B21="","",D21+E21-F21) -> 74062.58 | I21: 2 | J21: =IFERROR(IF(INDEX(Items!$U$5:$U$504,MATCH(LARGE(Items!$Z$5:$Z$504,2),Items!$Z$5:$Z$504,0))=0,"",INDEX(Items!$A$5:$A$504,MATCH(LARGE(Items!$Z$5:$Z$504,2),Items!$Z$5:$Z$504,0))),"") -> Basmati Rice 25kg | L21: =IF(J21="","",INDEX(Items!$U$5:$U$504,MATCH(LARGE(Items!$Z$5:$Z$504,2),Items!$Z$5:$Z$504,0))) -> 195710.58 | M21: =IF(J21="","",INDEX(Items!$O$5:$O$504,MATCH(LARGE(Items!$Z$5:$Z$504,2),Items!$Z$5:$Z$504,0))) -> 51 | N21: =IF(J21="","",INDEX(Items!$R$5:$R$504,MATCH(LARGE(Items!$Z$5:$Z$504,2),Items!$Z$5:$Z$504,0))) -> OK
B22: =IF(Settings!$A$20="","",Settings!$A$20) -> UPI | D22: =IF(B22="","",N(Settings!$B$20)) -> 0 | E22: =IF(B22="","",SUMIFS(CashBook!$I$5:INDEX(CashBook!$I$5:$I$3004,TxRows),CashBook!$F$5:INDEX(CashBook!$F$5:$F$3004,TxRows),B22,CashBook!$A$5:INDEX(CashBook!$A$5:$A$3004,TxRows),"<="&DTo)+SUMIFS(Sales!$X$5:INDEX(Sales!$X$5:$X$3004,TxRows),Sales!$H$5:INDEX(Sales!$H$5:$H$3004,TxRows),B22,Sales!$A$5:INDEX(Sales!$A$5:$A$3004,TxRows),"<="&DTo)) -> 384192.26 | F22: =IF(B22="","",SUMIFS(CashBook!$J$5:INDEX(CashBook!$J$5:$J$3004,TxRows),CashBook!$F$5:INDEX(CashBook!$F$5:$F$3004,TxRows),B22,CashBook!$A$5:INDEX(CashBook!$A$5:$A$3004,TxRows),"<="&DTo)+SUMIFS(Purchases!$S$5:INDEX(Purchases!$S$5:$S$3004,TxRows),Purchases!$H$5:INDEX(Purchases!$H$5:$H$3004,TxRows),B22,Purchases!$A$5:INDEX(Purchases!$A$5:$A$3004,TxRows),"<="&DTo)) -> 291973 | G22: =IF(B22="","",D22+E22-F22) -> 92219.26 | I22: 3 | J22: =IFERROR(IF(INDEX(Items!$U$5:$U$504,MATCH(LARGE(Items!$Z$5:$Z$504,3),Items!$Z$5:$Z$504,0))=0,"",INDEX(Items!$A$5:$A$504,MATCH(LARGE(Items!$Z$5:$Z$504,3),Items!$Z$5:$Z$504,0))),"") -> Sugar 50kg | L22: =IF(J22="","",INDEX(Items!$U$5:$U$504,MATCH(LARGE(Items!$Z$5:$Z$504,3),Items!$Z$5:$Z$504,0))) -> 140580.2 | M22: =IF(J22="","",INDEX(Items!$O$5:$O$504,MATCH(LARGE(Items!$Z$5:$Z$504,3),Items!$Z$5:$Z$504,0))) -> 23 | N22: =IF(J22="","",INDEX(Items!$R$5:$R$504,MATCH(LARGE(Items!$Z$5:$Z$504,3),Items!$Z$5:$Z$504,0))) -> OK
B23: =IF(Settings!$A$21="","",Settings!$A$21) | D23: =IF(B23="","",N(Settings!$B$21)) | E23: =IF(B23="","",SUMIFS(CashBook!$I$5:INDEX(CashBook!$I$5:$I$3004,TxRows),CashBook!$F$5:INDEX(CashBook!$F$5:$F$3004,TxRows),B23,CashBook!$A$5:INDEX(CashBook!$A$5:$A$3004,TxRows),"<="&DTo)+SUMIFS(Sales!$X$5:INDEX(Sales!$X$5:$X$3004,TxRows),Sales!$H$5:INDEX(Sales!$H$5:$H$3004,TxRows),B23,Sales!$A$5:INDEX(Sales!$A$5:$A$3004,TxRows),"<="&DTo)) | F23: =IF(B23="","",SUMIFS(CashBook!$J$5:INDEX(CashBook!$J$5:$J$3004,TxRows),CashBook!$F$5:INDEX(CashBook!$F$5:$F$3004,TxRows),B23,CashBook!$A$5:INDEX(CashBook!$A$5:$A$3004,TxRows),"<="&DTo)+SUMIFS(Purchases!$S$5:INDEX(Purchases!$S$5:$S$3004,TxRows),Purchases!$H$5:INDEX(Purchases!$H$5:$H$3004,TxRows),B23,Purchases!$A$5:INDEX(Purchases!$A$5:$A$3004,TxRows),"<="&DTo)) | G23: =IF(B23="","",D23+E23-F23) | I23: 4 | J23: =IFERROR(IF(INDEX(Items!$U$5:$U$504,MATCH(LARGE(Items!$Z$5:$Z$504,4),Items!$Z$5:$Z$504,0))=0,"",INDEX(Items!$A$5:$A$504,MATCH(LARGE(Items!$Z$5:$Z$504,4),Items!$Z$5:$Z$504,0))),"") -> Copper Wire 90m | L23: =IF(J23="","",INDEX(Items!$U$5:$U$504,MATCH(LARGE(Items!$Z$5:$Z$504,4),Items!$Z$5:$Z$504,0))) -> 129570.84 | M23: =IF(J23="","",INDEX(Items!$O$5:$O$504,MATCH(LARGE(Items!$Z$5:$Z$504,4),Items!$Z$5:$Z$504,0))) -> 14 | N23: =IF(J23="","",INDEX(Items!$R$5:$R$504,MATCH(LARGE(Items!$Z$5:$Z$504,4),Items!$Z$5:$Z$504,0))) -> OK
B24: TOTAL LIQUIDITY | G24: =SUM(G20:G23) -> 240608.64 | I24: 5 | J24: =IFERROR(IF(INDEX(Items!$U$5:$U$504,MATCH(LARGE(Items!$Z$5:$Z$504,5),Items!$Z$5:$Z$504,0))=0,"",INDEX(Items!$A$5:$A$504,MATCH(LARGE(Items!$Z$5:$Z$504,5),Items!$Z$5:$Z$504,0))),"") -> PVC Pipe 1in 6m | L24: =IF(J24="","",INDEX(Items!$U$5:$U$504,MATCH(LARGE(Items!$Z$5:$Z$504,5),Items!$Z$5:$Z$504,0))) -> 96569.55 | M24: =IF(J24="","",INDEX(Items!$O$5:$O$504,MATCH(LARGE(Items!$Z$5:$Z$504,5),Items!$Z$5:$Z$504,0))) -> 168 | N24: =IF(J24="","",INDEX(Items!$R$5:$R$504,MATCH(LARGE(Items!$Z$5:$Z$504,5),Items!$Z$5:$Z$504,0))) -> OK
I25: 6 | J25: =IFERROR(IF(INDEX(Items!$U$5:$U$504,MATCH(LARGE(Items!$Z$5:$Z$504,6),Items!$Z$5:$Z$504,0))=0,"",INDEX(Items!$A$5:$A$504,MATCH(LARGE(Items!$Z$5:$Z$504,6),Items!$Z$5:$Z$504,0))),"") -> LED Bulb 9W | L25: =IF(J25="","",INDEX(Items!$U$5:$U$504,MATCH(LARGE(Items!$Z$5:$Z$504,6),Items!$Z$5:$Z$504,0))) -> 93178.81 | M25: =IF(J25="","",INDEX(Items!$O$5:$O$504,MATCH(LARGE(Items!$Z$5:$Z$504,6),Items!$Z$5:$Z$504,0))) -> 366 | N25: =IF(J25="","",INDEX(Items!$R$5:$R$504,MATCH(LARGE(Items!$Z$5:$Z$504,6),Items!$Z$5:$Z$504,0))) -> OK
I26: 7 | J26: =IFERROR(IF(INDEX(Items!$U$5:$U$504,MATCH(LARGE(Items!$Z$5:$Z$504,7),Items!$Z$5:$Z$504,0))=0,"",INDEX(Items!$A$5:$A$504,MATCH(LARGE(Items!$Z$5:$Z$504,7),Items!$Z$5:$Z$504,0))),"") -> Ceiling Fan 1200mm | L26: =IF(J26="","",INDEX(Items!$U$5:$U$504,MATCH(LARGE(Items!$Z$5:$Z$504,7),Items!$Z$5:$Z$504,0))) -> 91510.02 | M26: =IF(J26="","",INDEX(Items!$O$5:$O$504,MATCH(LARGE(Items!$Z$5:$Z$504,7),Items!$Z$5:$Z$504,0))) -> 25 | N26: =IF(J26="","",INDEX(Items!$R$5:$R$504,MATCH(LARGE(Items!$Z$5:$Z$504,7),Items!$Z$5:$Z$504,0))) -> OK
I27: 8 | J27: =IFERROR(IF(INDEX(Items!$U$5:$U$504,MATCH(LARGE(Items!$Z$5:$Z$504,8),Items!$Z$5:$Z$504,0))=0,"",INDEX(Items!$A$5:$A$504,MATCH(LARGE(Items!$Z$5:$Z$504,8),Items!$Z$5:$Z$504,0))),"") -> Detergent 5kg | L27: =IF(J27="","",INDEX(Items!$U$5:$U$504,MATCH(LARGE(Items!$Z$5:$Z$504,8),Items!$Z$5:$Z$504,0))) -> 91039.25 | M27: =IF(J27="","",INDEX(Items!$O$5:$O$504,MATCH(LARGE(Items!$Z$5:$Z$504,8),Items!$Z$5:$Z$504,0))) -> 75 | N27: =IF(J27="","",INDEX(Items!$R$5:$R$504,MATCH(LARGE(Items!$Z$5:$Z$504,8),Items!$Z$5:$Z$504,0))) -> OK
I28: 9 | J28: =IFERROR(IF(INDEX(Items!$U$5:$U$504,MATCH(LARGE(Items!$Z$5:$Z$504,9),Items!$Z$5:$Z$504,0))=0,"",INDEX(Items!$A$5:$A$504,MATCH(LARGE(Items!$Z$5:$Z$504,9),Items!$Z$5:$Z$504,0))),"") -> Cement 50kg | L28: =IF(J28="","",INDEX(Items!$U$5:$U$504,MATCH(LARGE(Items!$Z$5:$Z$504,9),Items!$Z$5:$Z$504,0))) -> 86125.9 | M28: =IF(J28="","",INDEX(Items!$O$5:$O$504,MATCH(LARGE(Items!$Z$5:$Z$504,9),Items!$Z$5:$Z$504,0))) -> 216 | N28: =IF(J28="","",INDEX(Items!$R$5:$R$504,MATCH(LARGE(Items!$Z$5:$Z$504,9),Items!$Z$5:$Z$504,0))) -> OK
I29: 10 | J29: =IFERROR(IF(INDEX(Items!$U$5:$U$504,MATCH(LARGE(Items!$Z$5:$Z$504,10),Items!$Z$5:$Z$504,0))=0,"",INDEX(Items!$A$5:$A$504,MATCH(LARGE(Items!$Z$5:$Z$504,10),Items!$Z$5:$Z$504,0))),"") -> Tea Premium 1kg | L29: =IF(J29="","",INDEX(Items!$U$5:$U$504,MATCH(LARGE(Items!$Z$5:$Z$504,10),Items!$Z$5:$Z$504,0))) -> 61737.24 | M29: =IF(J29="","",INDEX(Items!$O$5:$O$504,MATCH(LARGE(Items!$Z$5:$Z$504,10),Items!$Z$5:$Z$504,0))) -> 92 | N29: =IF(J29="","",INDEX(Items!$R$5:$R$504,MATCH(LARGE(Items!$Z$5:$Z$504,10),Items!$Z$5:$Z$504,0))) -> OK

Sheet Sales
A1: SALES / INVOICES (DELIVER) | Z1: « Home
A2: One line per item sold. Keep all lines of an invoice together. Leave Rate blank to use the standard sale rate.
A3: Blue / cream = type here | J3: Grey = automatic (do not type)
A4: Date * | B4: Invoice No * | C4: Customer * | D4: Item * | E4: Qty * | F4: Rate (₹) blank=std | G4: Disc % | H4: Paid Via (blank=Credit) | I4: Delivery | J4: Unit | K4: Rate Used (₹) | L4: Taxable (₹) | M4: GST % | N4: CGST (₹) | O4: SGST (₹) | P4: IGST (₹) | Q4: Line Total (₹) | R4: COGS (₹) | S4: Profit (₹) | T4: Stock Check | U4: itemRow | V4: partyRow | W4: invNum | X4: Paid Now (₹)
A5: 46114 | B5: INV-0001 | C5: Sharma Kirana Store | D5: Basmati Rice 25kg | E5: 3 | G5: 0.02 | H5: Bank | I5: Delivered | J5: =IF($D5="","",IFERROR(INDEX(Items!$D$5:$D$504,U5),"")) -> Bag | K5: =IF($D5="","",IF($F5="",IFERROR(INDEX(Items!$H$5:$H$504,U5),0),$F5)) -> 2106 | L5: =IF($D5="","",ROUND(N($E5)*K5*(1-N($G5)),2)) -> 6191.64 | M5: =IF($D5="","",IFERROR(INDEX(Items!$F$5:$F$504,U5),0)) -> 0.05 | N5: =IF($D5="","",IF(AND(V5<>"",INDEX(Parties!$E$5:$E$304,V5)<>"",INDEX(Parties!$E$5:$E$304,V5)<>HomeState),0,ROUND(L5*M5/2,2))) -> 154.79 | O5: =IF($D5="","",N5) -> 154.79 | P5: =IF($D5="","",IF(AND(V5<>"",INDEX(Parties!$E$5:$E$304,V5)<>"",INDEX(Parties!$E$5:$E$304,V5)<>HomeState),ROUND(L5*M5,2),0)) -> 0 | Q5: =IF($D5="","",L5+N5+O5+P5) -> 6501.22 | R5: =IF($D5="","",ROUND(N($E5)*IFERROR(INDEX(Items!$P$5:$P$504,U5),0),2)) -> 4942.29 | S5: =IF($D5="","",L5-R5) -> 1249.35 | T5: =IF($D5="","",IF(U5="","UNKNOWN ITEM",IF(INDEX(Items!$O$5:$O$504,U5)<0,"NEG STOCK",IF(K5<INDEX(Items!$P$5:$P$504,U5),"BELOW COST","OK")))) -> OK | U5: =IF($D5="","",IFERROR(MATCH($D5,Items!$A$5:$A$504,0),"")) -> 1 | V5: =IF($C5="","",IFERROR(MATCH($C5,Parties!$A$5:$A$304,0),"")) -> 1 | W5: =IF($B5="","",IFERROR(VALUE(SUBSTITUTE($B5,InvPrefix,"")),0)) -> 1 | X5: =IF($D5="","",IF(OR($H5="",$H5="Credit"),0,Q5)) -> 6501.22
A6: 46116 | B6: INV-0002 | C6: Gupta Electricals | D6: Basmati Rice 25kg | E6: 8 | H6: Bank | I6: Delivered | J6: =IF($D6="","",IFERROR(INDEX(Items!$D$5:$D$504,U6),"")) -> Bag | K6: =IF($D6="","",IF($F6="",IFERROR(INDEX(Items!$H$5:$H$504,U6),0),$F6)) -> 2106 | L6: =IF($D6="","",ROUND(N($E6)*K6*(1-N($G6)),2)) -> 16848 | M6: =IF($D6="","",IFERROR(INDEX(Items!$F$5:$F$504,U6),0)) -> 0.05 | N6: =IF($D6="","",IF(AND(V6<>"",INDEX(Parties!$E$5:$E$304,V6)<>"",INDEX(Parties!$E$5:$E$304,V6)<>HomeState),0,ROUND(L6*M6/2,2))) -> 421.2 | O6: =IF($D6="","",N6) -> 421.2 | P6: =IF($D6="","",IF(AND(V6<>"",INDEX(Parties!$E$5:$E$304,V6)<>"",INDEX(Parties!$E$5:$E$304,V6)<>HomeState),ROUND(L6*M6,2),0)) -> 0 | Q6: =IF($D6="","",L6+N6+O6+P6) -> 17690.4 | R6: =IF($D6="","",ROUND(N($E6)*IFERROR(INDEX(Items!$P$5:$P$504,U6),0),2)) -> 13179.44 | S6: =IF($D6="","",L6-R6) -> 3668.56 | T6: =IF($D6="","",IF(U6="","UNKNOWN ITEM",IF(INDEX(Items!$O$5:$O$504,U6)<0,"NEG STOCK",IF(K6<INDEX(Items!$P$5:$P$504,U6),"BELOW COST","OK")))) -> OK | U6: =IF($D6="","",IFERROR(MATCH($D6,Items!$A$5:$A$504,0),"")) -> 1 | V6: =IF($C6="","",IFERROR(MATCH($C6,Parties!$A$5:$A$304,0),"")) -> 2 | W6: =IF($B6="","",IFERROR(VALUE(SUBSTITUTE($B6,InvPrefix,"")),0)) -> 2 | X6: =IF($D6="","",IF(OR($H6="",$H6="Credit"),0,Q6)) -> 17690.4
A7: 46119 | B7: INV-0003 | C7: Sharma Kirana Store | D7: PVC Pipe 1in 6m | E7: 32 | I7: Delivered | J7: =IF($D7="","",IFERROR(INDEX(Items!$D$5:$D$504,U7),"")) -> Pcs | K7: =IF($D7="","",IF($F7="",IFERROR(INDEX(Items!$H$5:$H$504,U7),0),$F7)) -> 297 | L7: =IF($D7="","",ROUND(N($E7)*K7*(1-N($G7)),2)) -> 9504 | M7: =IF($D7="","",IFERROR(INDEX(Items!$F$5:$F$504,U7),0)) -> 0.18 | N7: =IF($D7="","",IF(AND(V7<>"",INDEX(Parties!$E$5:$E$304,V7)<>"",INDEX(Parties!$E$5:$E$304,V7)<>HomeState),0,ROUND(L7*M7/2,2))) -> 855.36 | O7: =IF($D7="","",N7) -> 855.36 | P7: =IF($D7="","",IF(AND(V7<>"",INDEX(Parties!$E$5:$E$304,V7)<>"",INDEX(Parties!$E$5:$E$304,V7)<>HomeState),ROUND(L7*M7,2),0)) -> 0 | Q7: =IF($D7="","",L7+N7+O7+P7) -> 11214.72 | R7: =IF($D7="","",ROUND(N($E7)*IFERROR(INDEX(Items!$P$5:$P$504,U7),0),2)) -> 6708.26 | S7: =IF($D7="","",L7-R7) -> 2795.74 | T7: =IF($D7="","",IF(U7="","UNKNOWN ITEM",IF(INDEX(Items!$O$5:$O$504,U7)<0,"NEG STOCK",IF(K7<INDEX(Items!$P$5:$P$504,U7),"BELOW COST","OK")))) -> OK | U7: =IF($D7="","",IFERROR(MATCH($D7,Items!$A$5:$A$504,0),"")) -> 9 | V7: =IF($C7="","",IFERROR(MATCH($C7,Parties!$A$5:$A$304,0),"")) -> 1 | W7: =IF($B7="","",IFERROR(VALUE(SUBSTITUTE($B7,InvPrefix,"")),0)) -> 3 | X7: =IF($D7="","",IF(OR($H7="",$H7="Credit"),0,Q7)) -> 0
A8: 46120 | B8: INV-0004 | C8: Delhi Hardware Mart | D8: Cement 50kg | E8: 25 | H8: Bank | I8: Delivered | J8: =IF($D8="","",IFERROR(INDEX(Items!$D$5:$D$504,U8),"")) -> Bag | K8: =IF($D8="","",IF($F8="",IFERROR(INDEX(Items!$H$5:$H$504,U8),0),$F8)) -> 427 | L8: =IF($D8="","",ROUND(N($E8)*K8*(1-N($G8)),2)) -> 10675 | M8: =IF($D8="","",IFERROR(INDEX(Items!$F$5:$F$504,U8),0)) -> 0.18 | N8: =IF($D8="","",IF(AND(V8<>"",INDEX(Parties!$E$5:$E$304,V8)<>"",INDEX(Parties!$E$5:$E$304,V8)<>HomeState),0,ROUND(L8*M8/2,2))) -> 0 | O8: =IF($D8="","",N8) -> 0 | P8: =IF($D8="","",IF(AND(V8<>"",INDEX(Parties!$E$5:$E$304,V8)<>"",INDEX(Parties!$E$5:$E$304,V8)<>HomeState),ROUND(L8*M8,2),0)) -> 1921.5 | Q8: =IF($D8="","",L8+N8+O8+P8) -> 12596.5 | R8: =IF($D8="","",ROUND(N($E8)*IFERROR(INDEX(Items!$P$5:$P$504,U8),0),2)) -> 8504.36 | S8: =IF($D8="","",L8-R8) -> 2170.64 | T8: =IF($D8="","",IF(U8="","UNKNOWN ITEM",IF(INDEX(Items!$O$5:$O$504,U8)<0,"NEG STOCK",IF(K8<INDEX(Items!$P$5:$P$504,U8),"BELOW COST","OK")))) -> OK | U8: =IF($D8="","",IFERROR(MATCH($D8,Items!$A$5:$A$504,0),"")) -> 10 | V8: =IF($C8="","",IFERROR(MATCH($C8,Parties!$A$5:$A$304,0),"")) -> 3 | W8: =IF($B8="","",IFERROR(VALUE(SUBSTITUTE($B8,InvPrefix,"")),0)) -> 4 | X8: =IF($D8="","",IF(OR($H8="",$H8="Credit"),0,Q8)) -> 12596.5
A9: 46122 | B9: INV-0005 | C9: FMCG Distributors | D9: Ceiling Fan 1200mm | E9: 3 | G9: 0.05 | I9: Delivered | J9: =IF($D9="","",IFERROR(INDEX(Items!$D$5:$D$504,U9),"")) -> Pcs | K9: =IF($D9="","",IF($F9="",IFERROR(INDEX(Items!$H$5:$H$504,U9),0),$F9)) -> 2322 | L9: =IF($D9="","",ROUND(N($E9)*K9*(1-N($G9)),2)) -> 6617.7 | M9: =IF($D9="","",IFERROR(INDEX(Items!$F$5:$F$504,U9),0)) -> 0.18 | N9: =IF($D9="","",IF(AND(V9<>"",INDEX(Parties!$E$5:$E$304,V9)<>"",INDEX(Parties!$E$5:$E$304,V9)<>HomeState),0,ROUND(L9*M9/2,2))) -> 595.59 | O9: =IF($D9="","",N9) -> 595.59 | P9: =IF($D9="","",IF(AND(V9<>"",INDEX(Parties!$E$5:$E$304,V9)<>"",INDEX(Parties!$E$5:$E$304,V9)<>HomeState),ROUND(L9*M9,2),0)) -> 0 | Q9: =IF($D9="","",L9+N9+O9+P9) -> 7808.88 | R9: =IF($D9="","",ROUND(N($E9)*IFERROR(INDEX(Items!$P$5:$P$504,U9),0),2)) -> 4931.4 | S9: =IF($D9="","",L9-R9) -> 1686.3 | T9: =IF($D9="","",IF(U9="","UNKNOWN ITEM",IF(INDEX(Items!$O$5:$O$504,U9)<0,"NEG STOCK",IF(K9<INDEX(Items!$P$5:$P$504,U9),"BELOW COST","OK")))) -> OK | U9: =IF($D9="","",IFERROR(MATCH($D9,Items!$A$5:$A$504,0),"")) -> 12 | V9: =IF($C9="","",IFERROR(MATCH($C9,Parties!$A$5:$A$304,0),"")) -> 9 | W9: =IF($B9="","",IFERROR(VALUE(SUBSTITUTE($B9,InvPrefix,"")),0)) -> 5 | X9: =IF($D9="","",IF(OR($H9="",$H9="Credit"),0,Q9)) -> 0
A10: 46122 | B10: INV-0005 | C10: FMCG Distributors | D10: Sugar 50kg | E10: 3 | G10: 0.05 | I10: Delivered | J10: =IF($D10="","",IFERROR(INDEX(Items!$D$5:$D$504,U10),"")) -> Bag | K10: =IF($D10="","",IF($F10="",IFERROR(INDEX(Items!$H$5:$H$504,U10),0),$F10)) -> 2462 | L10: =IF($D10="","",ROUND(N($E10)*K10*(1-N($G10)),2)) -> 7016.7 | M10: =IF($D10="","",IFERROR(INDEX(Items!$F$5:$F$504,U10),0)) -> 0.05 | N10: =IF($D10="","",IF(AND(V10<>"",INDEX(Parties!$E$5:$E$304,V10)<>"",INDEX(Parties!$E$5:$E$304,V10)<>HomeState),0,ROUND(L10*M10/2,2))) -> 175.42 | O10: =IF($D10="","",N10) -> 175.42 | P10: =IF($D10="","",IF(AND(V10<>"",INDEX(Parties!$E$5:$E$304,V10)<>"",INDEX(Parties!$E$5:$E$304,V10)<>HomeState),ROUND(L10*M10,2),0)) -> 0 | Q10: =IF($D10="","",L10+N10+O10+P10) -> 7367.54 | R10: =IF($D10="","",ROUND(N($E10)*IFERROR(INDEX(Items!$P$5:$P$504,U10),0),2)) -> 6113.19 | S10: =IF($D10="","",L10-R10) -> 903.51 | T10: =IF($D10="","",IF(U10="","UNKNOWN ITEM",IF(INDEX(Items!$O$5:$O$504,U10)<0,"NEG STOCK",IF(K10<INDEX(Items!$P$5:$P$504,U10),"BELOW COST","OK")))) -> OK | U10: =IF($D10="","",IFERROR(MATCH($D10,Items!$A$5:$A$504,0),"")) -> 2 | V10: =IF($C10="","",IFERROR(MATCH($C10,Parties!$A$5:$A$304,0),"")) -> 9 | W10: =IF($B10="","",IFERROR(VALUE(SUBSTITUTE($B10,InvPrefix,"")),0)) -> 5 | X10: =IF($D10="","",IF(OR($H10="",$H10="Credit"),0,Q10)) -> 0
A11: 46123 | B11: INV-0006 | C11: Mehta Constructions | D11: Sugar 50kg | E11: 5 | H11: Bank | I11: Delivered | J11: =IF($D11="","",IFERROR(INDEX(Items!$D$5:$D$504,U11),"")) -> Bag | K11: =IF($D11="","",IF($F11="",IFERROR(INDEX(Items!$H$5:$H$504,U11),0),$F11)) -> 2462 | L11: =IF($D11="","",ROUND(N($E11)*K11*(1-N($G11)),2)) -> 12310 | M11: =IF($D11="","",IFERROR(INDEX(Items!$F$5:$F$504,U11),0)) -> 0.05 | N11: =IF($D11="","",IF(AND(V11<>"",INDEX(Parties!$E$5:$E$304,V11)<>"",INDEX(Parties!$E$5:$E$304,V11)<>HomeState),0,ROUND(L11*M11/2,2))) -> 307.75 | O11: =IF($D11="","",N11) -> 307.75 | P11: =IF($D11="","",IF(AND(V11<>"",INDEX(Parties!$E$5:$E$304,V11)<>"",INDEX(Parties!$E$5:$E$304,V11)<>HomeState),ROUND(L11*M11,2),0)) -> 0 | Q11: =IF($D11="","",L11+N11+O11+P11) -> 12925.5 | R11: =IF($D11="","",ROUND(N($E11)*IFERROR(INDEX(Items!$P$5:$P$504,U11),0),2)) -> 10188.64 | S11: =IF($D11="","",L11-R11) -> 2121.36 | T11: =IF($D11="","",IF(U11="","UNKNOWN ITEM",IF(INDEX(Items!$O$5:$O$504,U11)<0,"NEG STOCK",IF(K11<INDEX(Items!$P$5:$P$504,U11),"BELOW COST","OK")))) -> OK | U11: =IF($D11="","",IFERROR(MATCH($D11,Items!$A$5:$A$504,0),"")) -> 2 | V11: =IF($C11="","",IFERROR(MATCH($C11,Parties!$A$5:$A$304,0),"")) -> 5 | W11: =IF($B11="","",IFERROR(VALUE(SUBSTITUTE($B11,InvPrefix,"")),0)) -> 6 | X11: =IF($D11="","",IF(OR($H11="",$H11="Credit"),0,Q11)) -> 12925.5
A12: 46125 | B12: INV-0007 | C12: Delhi Hardware Mart | D12: Basmati Rice 25kg | E12: 8 | H12: UPI | I12: Delivered | J12: =IF($D12="","",IFERROR(INDEX(Items!$D$5:$D$504,U12),"")) -> Bag | K12: =IF($D12="","",IF($F12="",IFERROR(INDEX(Items!$H$5:$H$504,U12),0),$F12)) -> 2106 | L12: =IF($D12="","",ROUND(N($E12)*K12*(1-N($G12)),2)) -> 16848 | M12: =IF($D12="","",IFERROR(INDEX(Items!$F$5:$F$504,U12),0)) -> 0.05 | N12: =IF($D12="","",IF(AND(V12<>"",INDEX(Parties!$E$5:$E$304,V12)<>"",INDEX(Parties!$E$5:$E$304,V12)<>HomeState),0,ROUND(L12*M12/2,2))) -> 0 | O12: =IF($D12="","",N12) -> 0 | P12: =IF($D12="","",IF(AND(V12<>"",INDEX(Parties!$E$5:$E$304,V12)<>"",INDEX(Parties!$E$5:$E$304,V12)<>HomeState),ROUND(L12*M12,2),0)) -> 842.4 | Q12: =IF($D12="","",L12+N12+O12+P12) -> 17690.4 | R12: =IF($D12="","",ROUND(N($E12)*IFERROR(INDEX(Items!$P$5:$P$504,U12),0),2)) -> 13179.44 | S12: =IF($D12="","",L12-R12) -> 3668.56 | T12: =IF($D12="","",IF(U12="","UNKNOWN ITEM",IF(INDEX(Items!$O$5:$O$504,U12)<0,"NEG STOCK",IF(K12<INDEX(Items!$P$5:$P$504,U12),"BELOW COST","OK")))) -> OK | U12: =IF($D12="","",IFERROR(MATCH($D12,Items!$A$5:$A$504,0),"")) -> 1 | V12: =IF($C12="","",IFERROR(MATCH($C12,Parties!$A$5:$A$304,0),"")) -> 3 | W12: =IF($B12="","",IFERROR(VALUE(SUBSTITUTE($B12,InvPrefix,"")),0)) -> 7 | X12: =IF($D12="","",IF(OR($H12="",$H12="Credit"),0,Q12)) -> 17690.4
A13: 46126 | B13: INV-0008 | C13: FMCG Distributors | D13: Copper Wire 90m | E13: 3 | I13: Delivered | J13: =IF($D13="","",IFERROR(INDEX(Items!$D$5:$D$504,U13),"")) -> Pcs | K13: =IF($D13="","",IF($F13="",IFERROR(INDEX(Items!$H$5:$H$504,U13),0),$F13)) -> 3132 | L13: =IF($D13="","",ROUND(N($E13)*K13*(1-N($G13)),2)) -> 9396 | M13: =IF($D13="","",IFERROR(INDEX(Items!$F$5:$F$504,U13),0)) -> 0.18 | N13: =IF($D13="","",IF(AND(V13<>"",INDEX(Parties!$E$5:$E$304,V13)<>"",INDEX(Parties!$E$5:$E$304,V13)<>HomeState),0,ROUND(L13*M13/2,2))) -> 845.64 | O13: =IF($D13="","",N13) -> 845.64 | P13: =IF($D13="","",IF(AND(V13<>"",INDEX(Parties!$E$5:$E$304,V13)<>"",INDEX(Parties!$E$5:$E$304,V13)<>HomeState),ROUND(L13*M13,2),0)) -> 0 | Q13: =IF($D13="","",L13+N13+O13+P13) -> 11087.28 | R13: =IF($D13="","",ROUND(N($E13)*IFERROR(INDEX(Items!$P$5:$P$504,U13),0),2)) -> 7354.45 | S13: =IF($D13="","",L13-R13) -> 2041.55 | T13: =IF($D13="","",IF(U13="","UNKNOWN ITEM",IF(INDEX(Items!$O$5:$O$504,U13)<0,"NEG STOCK",IF(K13<INDEX(Items!$P$5:$P$504,U13),"BELOW COST","OK")))) -> OK | U13: =IF($D13="","",IFERROR(MATCH($D13,Items!$A$5:$A$504,0),"")) -> 8 | V13: =IF($C13="","",IFERROR(MATCH($C13,Parties!$A$5:$A$304,0),"")) -> 9 | W13: =IF($B13="","",IFERROR(VALUE(SUBSTITUTE($B13,InvPrefix,"")),0)) -> 8 | X13: =IF($D13="","",IF(OR($H13="",$H13="Credit"),0,Q13)) -> 0
A14: 46126 | B14: INV-0008 | C14: FMCG Distributors | D14: Cement 50kg | E14: 40 | I14: Delivered | J14: =IF($D14="","",IFERROR(INDEX(Items!$D$5:$D$504,U14),"")) -> Bag | K14: =IF($D14="","",IF($F14="",IFERROR(INDEX(Items!$H$5:$H$504,U14),0),$F14)) -> 427 | L14: =IF($D14="","",ROUND(N($E14)*K14*(1-N($G14)),2)) -> 17080 | M14: =IF($D14="","",IFERROR(INDEX(Items!$F$5:$F$504,U14),0)) -> 0.18 | N14: =IF($D14="","",IF(AND(V14<>"",INDEX(Parties!$E$5:$E$304,V14)<>"",INDEX(Parties!$E$5:$E$304,V14)<>HomeState),0,ROUND(L14*M14/2,2))) -> 1537.2 | O14: =IF($D14="","",N14) -> 1537.2 | P14: =IF($D14="","",IF(AND(V14<>"",INDEX(Parties!$E$5:$E$304,V14)<>"",INDEX(Parties!$E$5:$E$304,V14)<>HomeState),ROUND(L14*M14,2),0)) -> 0 | Q14: =IF($D14="","",L14+N14+O14+P14) -> 20154.4 | R14: =IF($D14="","",ROUND(N($E14)*IFERROR(INDEX(Items!$P$5:$P$504,U14),0),2)) -> 13606.97 | S14: =IF($D14="","",L14-R14) -> 3473.03 | T14: =IF($D14="","",IF(U14="","UNKNOWN ITEM",IF(INDEX(Items!$O$5:$O$504,U14)<0,"NEG STOCK",IF(K14<INDEX(Items!$P$5:$P$504,U14),"BELOW COST","OK")))) -> OK | U14: =IF($D14="","",IFERROR(MATCH($D14,Items!$A$5:$A$504,0),"")) -> 10 | V14: =IF($C14="","",IFERROR(MATCH($C14,Parties!$A$5:$A$304,0),"")) -> 9 | W14: =IF($B14="","",IFERROR(VALUE(SUBSTITUTE($B14,InvPrefix,"")),0)) -> 8 | X14: =IF($D14="","",IF(OR($H14="",$H14="Credit"),0,Q14)) -> 0
A15: 46127 | B15: INV-0009 | C15: Gupta Electricals | D15: Ceiling Fan 1200mm | E15: 3 | G15: 0.02 | I15: Delivered | J15: =IF($D15="","",IFERROR(INDEX(Items!$D$5:$D$504,U15),"")) -> Pcs | K15: =IF($D15="","",IF($F15="",IFERROR(INDEX(Items!$H$5:$H$504,U15),0),$F15)) -> 2322 | L15: =IF($D15="","",ROUND(N($E15)*K15*(1-N($G15)),2)) -> 6826.68 | M15: =IF($D15="","",IFERROR(INDEX(Items!$F$5:$F$504,U15),0)) -> 0.18 | N15: =IF($D15="","",IF(AND(V15<>"",INDEX(Parties!$E$5:$E$304,V15)<>"",INDEX(Parties!$E$5:$E$304,V15)<>HomeState),0,ROUND(L15*M15/2,2))) -> 614.4 | O15: =IF($D15="","",N15) -> 614.4 | P15: =IF($D15="","",IF(AND(V15<>"",INDEX(Parties!$E$5:$E$304,V15)<>"",INDEX(Parties!$E$5:$E$304,V15)<>HomeState),ROUND(L15*M15,2),0)) -> 0 | Q15: =IF($D15="","",L15+N15+O15+P15) -> 8055.48 | R15: =IF($D15="","",ROUND(N($E15)*IFERROR(INDEX(Items!$P$5:$P$504,U15),0),2)) -> 4931.4 | S15: =IF($D15="","",L15-R15) -> 1895.28 | T15: =IF($D15="","",IF(U15="","UNKNOWN ITEM",IF(INDEX(Items!$O$5:$O$504,U15)<0,"NEG STOCK",IF(K15<INDEX(Items!$P$5:$P$504,U15),"BELOW COST","OK")))) -> OK | U15: =IF($D15="","",IFERROR(MATCH($D15,Items!$A$5:$A$504,0),"")) -> 12 | V15: =IF($C15="","",IFERROR(MATCH($C15,Parties!$A$5:$A$304,0),"")) -> 2 | W15: =IF($B15="","",IFERROR(VALUE(SUBSTITUTE($B15,InvPrefix,"")),0)) -> 9 | X15: =IF($D15="","",IF(OR($H15="",$H15="Credit"),0,Q15)) -> 0
A16: 46127 | B16: INV-0009 | C16: Gupta Electricals | D16: Detergent 5kg | E16: 7 | G16: 0.02 | I16: Delivered | J16: =IF($D16="","",IFERROR(INDEX(Items!$D$5:$D$504,U16),"")) -> Pack | K16: =IF($D16="","",IF($F16="",IFERROR(INDEX(Items!$H$5:$H$504,U16),0),$F16)) -> 691 | L16: =IF($D16="","",ROUND(N($E16)*K16*(1-N($G16)),2)) -> 4740.26 | M16: =IF($D16="","",IFERROR(INDEX(Items!$F$5:$F$504,U16),0)) -> 0.18 | N16: =IF($D16="","",IF(AND(V16<>"",INDEX(Parties!$E$5:$E$304,V16)<>"",INDEX(Parties!$E$5:$E$304,V16)<>HomeState),0,ROUND(L16*M16/2,2))) -> 426.62 | O16: =IF($D16="","",N16) -> 426.62 | P16: =IF($D16="","",IF(AND(V16<>"",INDEX(Parties!$E$5:$E$304,V16)<>"",INDEX(Parties!$E$5:$E$304,V16)<>HomeState),ROUND(L16*M16,2),0)) -> 0 | Q16: =IF($D16="","",L16+N16+O16+P16) -> 5593.5 | R16: =IF($D16="","",ROUND(N($E16)*IFERROR(INDEX(Items!$P$5:$P$504,U16),0),2)) -> 3623.85 | S16: =IF($D16="","",L16-R16) -> 1116.41 | T16: =IF($D16="","",IF(U16="","UNKNOWN ITEM",IF(INDEX(Items!$O$5:$O$504,U16)<0,"NEG STOCK",IF(K16<INDEX(Items!$P$5:$P$504,U16),"BELOW COST","OK")))) -> OK | U16: =IF($D16="","",IFERROR(MATCH($D16,Items!$A$5:$A$504,0),"")) -> 5 | V16: =IF($C16="","",IFERROR(MATCH($C16,Parties!$A$5:$A$304,0),"")) -> 2 | W16: =IF($B16="","",IFERROR(VALUE(SUBSTITUTE($B16,InvPrefix,"")),0)) -> 9 | X16: =IF($D16="","",IF(OR($H16="",$H16="Credit"),0,Q16)) -> 0
A17: 46128 | B17: INV-0010 | C17: Sharma Kirana Store | D17: Refined Oil 15L | E17: 6 | G17: 0.02 | H17: UPI | I17: Delivered | J17: =IF($D17="","",IFERROR(INDEX(Items!$D$5:$D$504,U17),"")) -> Box | K17: =IF($D17="","",IF($F17="",IFERROR(INDEX(Items!$H$5:$H$504,U17),0),$F17)) -> 2290 | L17: =IF($D17="","",ROUND(N($E17)*K17*(1-N($G17)),2)) -> 13465.2 | M17: =IF($D17="","",IFERROR(INDEX(Items!$F$5:$F$504,U17),0)) -> 0.05 | N17: =IF($D17="","",IF(AND(V17<>"",INDEX(Parties!$E$5:$E$304,V17)<>"",INDEX(Parties!$E$5:$E$304,V17)<>HomeState),0,ROUND(L17*M17/2,2))) -> 336.63 | O17: =IF($D17="","",N17) -> 336.63 | P17: =IF($D17="","",IF(AND(V17<>"",INDEX(Parties!$E$5:$E$304,V17)<>"",INDEX(Parties!$E$5:$E$304,V17)<>HomeState),ROUND(L17*M17,2),0)) -> 0 | Q17: =IF($D17="","",L17+N17+O17+P17) -> 14138.46 | R17: =IF($D17="","",ROUND(N($E17)*IFERROR(INDEX(Items!$P$5:$P$504,U17),0),2)) -> 11426.18 | S17: =IF($D17="","",L17-R17) -> 2039.02 | T17: =IF($D17="","",IF(U17="","UNKNOWN ITEM",IF(INDEX(Items!$O$5:$O$504,U17)<0,"NEG STOCK",IF(K17<INDEX(Items!$P$5:$P$504,U17),"BELOW COST","OK")))) -> OK | U17: =IF($D17="","",IFERROR(MATCH($D17,Items!$A$5:$A$504,0),"")) -> 3 | V17: =IF($C17="","",IFERROR(MATCH($C17,Parties!$A$5:$A$304,0),"")) -> 1 | W17: =IF($B17="","",IFERROR(VALUE(SUBSTITUTE($B17,InvPrefix,"")),0)) -> 10 | X17: =IF($D17="","",IF(OR($H17="",$H17="Credit"),0,Q17)) -> 14138.46
A18: 46130 | B18: INV-0011 | C18: Mehta Constructions | D18: Tea Premium 1kg | E18: 11 | G18: 0.02 | I18: Delivered | J18: =IF($D18="","",IFERROR(INDEX(Items!$D$5:$D$504,U18),"")) -> Pack | K18: =IF($D18="","",IF($F18="",IFERROR(INDEX(Items!$H$5:$H$504,U18),0),$F18)) -> 508 | L18: =IF($D18="","",ROUND(N($E18)*K18*(1-N($G18)),2)) -> 5476.24 | M18: =IF($D18="","",IFERROR(INDEX(Items!$F$5:$F$504,U18),0)) -> 0.05 | N18: =IF($D18="","",IF(AND(V18<>"",INDEX(Parties!$E$5:$E$304,V18)<>"",INDEX(Parties!$E$5:$E$304,V18)<>HomeState),0,ROUND(L18*M18/2,2))) -> 136.91 | O18: =IF($D18="","",N18) -> 136.91 | P18: =IF($D18="","",IF(AND(V18<>"",INDEX(Parties!$E$5:$E$304,V18)<>"",INDEX(Parties!$E$5:$E$304,V18)<>HomeState),ROUND(L18*M18,2),0)) -> 0 | Q18: =IF($D18="","",L18+N18+O18+P18) -> 5750.06 | R18: =IF($D18="","",ROUND(N($E18)*IFERROR(INDEX(Items!$P$5:$P$504,U18),0),2)) -> 4147.87 | S18: =IF($D18="","",L18-R18) -> 1328.37 | T18: =IF($D18="","",IF(U18="","UNKNOWN ITEM",IF(INDEX(Items!$O$5:$O$504,U18)<0,"NEG STOCK",IF(K18<INDEX(Items!$P$5:$P$504,U18),"BELOW COST","OK")))) -> OK | U18: =IF($D18="","",IFERROR(MATCH($D18,Items!$A$5:$A$504,0),"")) -> 4 | V18: =IF($C18="","",IFERROR(MATCH($C18,Parties!$A$5:$A$304,0),"")) -> 5 | W18: =IF($B18="","",IFERROR(VALUE(SUBSTITUTE($B18,InvPrefix,"")),0)) -> 11 | X18: =IF($D18="","",IF(OR($H18="",$H18="Credit"),0,Q18)) -> 0
A19: 46130 | B19: INV-0011 | C19: Mehta Constructions | D19: LED Bulb 9W | E19: 39 | G19: 0.02 | I19: Delivered | J19: =IF($D19="","",IFERROR(INDEX(Items!$D$5:$D$504,U19),"")) -> Pcs | K19: =IF($D19="","",IF($F19="",IFERROR(INDEX(Items!$H$5:$H$504,U19),0),$F19)) -> 107 | L19: =IF($D19="","",ROUND(N($E19)*K19*(1-N($G19)),2)) -> 4089.54 | M19: =IF($D19="","",IFERROR(INDEX(Items!$F$5:$F$504,U19),0)) -> 0.18 | N19: =IF($D19="","",IF(AND(V19<>"",INDEX(Parties!$E$5:$E$304,V19)<>"",INDEX(Parties!$E$5:$E$304,V19)<>HomeState),0,ROUND(L19*M19/2,2))) -> 368.06 | O19: =IF($D19="","",N19) -> 368.06 | P19: =IF($D19="","",IF(AND(V19<>"",INDEX(Parties!$E$5:$E$304,V19)<>"",INDEX(Parties!$E$5:$E$304,V19)<>HomeState),ROUND(L19*M19,2),0)) -> 0 | Q19: =IF($D19="","",L19+N19+O19+P19) -> 4825.66 | R19: =IF($D19="","",ROUND(N($E19)*IFERROR(INDEX(Items!$P$5:$P$504,U19),0),2)) -> 2395.27 | S19: =IF($D19="","",L19-R19) -> 1694.27 | T19: =IF($D19="","",IF(U19="","UNKNOWN ITEM",IF(INDEX(Items!$O$5:$O$504,U19)<0,"NEG STOCK",IF(K19<INDEX(Items!$P$5:$P$504,U19),"BELOW COST","OK")))) -> OK | U19: =IF($D19="","",IFERROR(MATCH($D19,Items!$A$5:$A$504,0),"")) -> 7 | V19: =IF($C19="","",IFERROR(MATCH($C19,Parties!$A$5:$A$304,0),"")) -> 5 | W19: =IF($B19="","",IFERROR(VALUE(SUBSTITUTE($B19,InvPrefix,"")),0)) -> 11 | X19: =IF($D19="","",IF(OR($H19="",$H19="Credit"),0,Q19)) -> 0
A20: 46132 | B20: INV-0012 | C20: Mehta Constructions | D20: PVC Pipe 1in 6m | E20: 20 | G20: 0.02 | I20: Delivered | J20: =IF($D20="","",IFERROR(INDEX(Items!$D$5:$D$504,U20),"")) -> Pcs | K20: =IF($D20="","",IF($F20="",IFERROR(INDEX(Items!$H$5:$H$504,U20),0),$F20)) -> 297 | L20: =IF($D20="","",ROUND(N($E20)*K20*(1-N($G20)),2)) -> 5821.2 | M20: =IF($D20="","",IFERROR(INDEX(Items!$F$5:$F$504,U20),0)) -> 0.18 | N20: =IF($D20="","",IF(AND(V20<>"",INDEX(Parties!$E$5:$E$304,V20)<>"",INDEX(Parties!$E$5:$E$304,V20)<>HomeState),0,ROUND(L20*M20/2,2))) -> 523.91 | O20: =IF($D20="","",N20) -> 523.91 | P20: =IF($D20="","",IF(AND(V20<>"",INDEX(Parties!$E$5:$E$304,V20)<>"",INDEX(Parties!$E$5:$E$304,V20)<>HomeState),ROUND(L20*M20,2),0)) -> 0 | Q20: =IF($D20="","",L20+N20+O20+P20) -> 6869.02 | R20: =IF($D20="","",ROUND(N($E20)*IFERROR(INDEX(Items!$P$5:$P$504,U20),0),2)) -> 4192.67 | S20: =IF($D20="","",L20-R20) -> 1628.53 | T20: =IF($D20="","",IF(U20="","UNKNOWN ITEM",IF(INDEX(Items!$O$5:$O$504,U20)<0,"NEG STOCK",IF(K20<INDEX(Items!$P$5:$P$504,U20),"BELOW COST","OK")))) -> OK | U20: =IF($D20="","",IFERROR(MATCH($D20,Items!$A$5:$A$504,0),"")) -> 9 | V20: =IF($C20="","",IFERROR(MATCH($C20,Parties!$A$5:$A$304,0),"")) -> 5 | W20: =IF($B20="","",IFERROR(VALUE(SUBSTITUTE($B20,InvPrefix,"")),0)) -> 12 | X20: =IF($D20="","",IF(OR($H20="",$H20="Credit"),0,Q20)) -> 0
A21: 46133 | B21: INV-0013 | C21: Walk-in Customer | D21: Refined Oil 15L | E21: 3 | H21: Cash | I21: Delivered | J21: =IF($D21="","",IFERROR(INDEX(Items!$D$5:$D$504,U21),"")) -> Box | K21: =IF($D21="","",IF($F21="",IFERROR(INDEX(Items!$H$5:$H$504,U21),0),$F21)) -> 2290 | L21: =IF($D21="","",ROUND(N($E21)*K21*(1-N($G21)),2)) -> 6870 | M21: =IF($D21="","",IFERROR(INDEX(Items!$F$5:$F$504,U21),0)) -> 0.05 | N21: =IF($D21="","",IF(AND(V21<>"",INDEX(Parties!$E$5:$E$304,V21)<>"",INDEX(Parties!$E$5:$E$304,V21)<>HomeState),0,ROUND(L21*M21/2,2))) -> 171.75 | O21: =IF($D21="","",N21) -> 171.75 | P21: =IF($D21="","",IF(AND(V21<>"",INDEX(Parties!$E$5:$E$304,V21)<>"",INDEX(Parties!$E$5:$E$304,V21)<>HomeState),ROUND(L21*M21,2),0)) -> 0 | Q21: =IF($D21="","",L21+N21+O21+P21) -> 7213.5 | R21: =IF($D21="","",ROUND(N($E21)*IFERROR(INDEX(Items!$P$5:$P$504,U21),0),2)) -> 5713.09 | S21: =IF($D21="","",L21-R21) -> 1156.91 | T21: =IF($D21="","",IF(U21="","UNKNOWN ITEM",IF(INDEX(Items!$O$5:$O$504,U21)<0,"NEG STOCK",IF(K21<INDEX(Items!$P$5:$P$504,U21),"BELOW COST","OK")))) -> OK | U21: =IF($D21="","",IFERROR(MATCH($D21,Items!$A$5:$A$504,0),"")) -> 3 | V21: =IF($C21="","",IFERROR(MATCH($C21,Parties!$A$5:$A$304,0),"")) -> 4 | W21: =IF($B21="","",IFERROR(VALUE(SUBSTITUTE($B21,InvPrefix,"")),0)) -> 13 | X21: =IF($D21="","",IF(OR($H21="",$H21="Credit"),0,Q21)) -> 7213.5
A22: 46134 | B22: INV-0014 | C22: Walk-in Customer | D22: Copper Wire 90m | E22: 4 | H22: Cash | I22: Delivered | J22: =IF($D22="","",IFERROR(INDEX(Items!$D$5:$D$504,U22),"")) -> Pcs | K22: =IF($D22="","",IF($F22="",IFERROR(INDEX(Items!$H$5:$H$504,U22),0),$F22)) -> 3132 | L22: =IF($D22="","",ROUND(N($E22)*K22*(1-N($G22)),2)) -> 12528 | M22: =IF($D22="","",IFERROR(INDEX(Items!$F$5:$F$504,U22),0)) -> 0.18 | N22: =IF($D22="","",IF(AND(V22<>"",INDEX(Parties!$E$5:$E$304,V22)<>"",INDEX(Parties!$E$5:$E$304,V22)<>HomeState),0,ROUND(L22*M22/2,2))) -> 1127.52 | O22: =IF($D22="","",N22) -> 1127.52 | P22: =IF($D22="","",IF(AND(V22<>"",INDEX(Parties!$E$5:$E$304,V22)<>"",INDEX(Parties!$E$5:$E$304,V22)<>HomeState),ROUND(L22*M22,2),0)) -> 0 | Q22: =IF($D22="","",L22+N22+O22+P22) -> 14783.04 | R22: =IF($D22="","",ROUND(N($E22)*IFERROR(INDEX(Items!$P$5:$P$504,U22),0),2)) -> 9805.93 | S22: =IF($D22="","",L22-R22) -> 2722.07 | T22: =IF($D22="","",IF(U22="","UNKNOWN ITEM",IF(INDEX(Items!$O$5:$O$504,U22)<0,"NEG STOCK",IF(K22<INDEX(Items!$P$5:$P$504,U22),"BELOW COST","OK")))) -> OK | U22: =IF($D22="","",IFERROR(MATCH($D22,Items!$A$5:$A$504,0),"")) -> 8 | V22: =IF($C22="","",IFERROR(MATCH($C22,Parties!$A$5:$A$304,0),"")) -> 4 | W22: =IF($B22="","",IFERROR(VALUE(SUBSTITUTE($B22,InvPrefix,"")),0)) -> 14 | X22: =IF($D22="","",IF(OR($H22="",$H22="Credit"),0,Q22)) -> 14783.04
A23: 46135 | B23: INV-0015 | C23: Mehta Constructions | D23: LED Bulb 9W | E23: 64 | G23: 0.05 | I23: Delivered | J23: =IF($D23="","",IFERROR(INDEX(Items!$D$5:$D$504,U23),"")) -> Pcs | K23: =IF($D23="","",IF($F23="",IFERROR(INDEX(Items!$H$5:$H$504,U23),0),$F23)) -> 107 | L23: =IF($D23="","",ROUND(N($E23)*K23*(1-N($G23)),2)) -> 6505.6 | M23: =IF($D23="","",IFERROR(INDEX(Items!$F$5:$F$504,U23),0)) -> 0.18 | N23: =IF($D23="","",IF(AND(V23<>"",INDEX(Parties!$E$5:$E$304,V23)<>"",INDEX(Parties!$E$5:$E$304,V23)<>HomeState),0,ROUND(L23*M23/2,2))) -> 585.5 | O23: =IF($D23="","",N23) -> 585.5 | P23: =IF($D23="","",IF(AND(V23<>"",INDEX(Parties!$E$5:$E$304,V23)<>"",INDEX(Parties!$E$5:$E$304,V23)<>HomeState),ROUND(L23*M23,2),0)) -> 0 | Q23: =IF($D23="","",L23+N23+O23+P23) -> 7676.6 | R23: =IF($D23="","",ROUND(N($E23)*IFERROR(INDEX(Items!$P$5:$P$504,U23),0),2)) -> 3930.69 | S23: =IF($D23="","",L23-R23) -> 2574.91 | T23: =IF($D23="","",IF(U23="","UNKNOWN ITEM",IF(INDEX(Items!$O$5:$O$504,U23)<0,"NEG STOCK",IF(K23<INDEX(Items!$P$5:$P$504,U23),"BELOW COST","OK")))) -> OK | U23: =IF($D23="","",IFERROR(MATCH($D23,Items!$A$5:$A$504,0),"")) -> 7 | V23: =IF($C23="","",IFERROR(MATCH($C23,Parties!$A$5:$A$304,0),"")) -> 5 | W23: =IF($B23="","",IFERROR(VALUE(SUBSTITUTE($B23,InvPrefix,"")),0)) -> 15 | X23: =IF($D23="","",IF(OR($H23="",$H23="Credit"),0,Q23)) -> 0
A24: 46136 | B24: INV-0016 | C24: Delhi Hardware Mart | D24: A4 Paper Ream | E24: 22 | G24: 0.02 | H24: Bank | I24: Delivered | J24: =IF($D24="","",IFERROR(INDEX(Items!$D$5:$D$504,U24),"")) -> Pack | K24: =IF($D24="","",IF($F24="",IFERROR(INDEX(Items!$H$5:$H$504,U24),0),$F24)) -> 335 | L24: =IF($D24="","",ROUND(N($E24)*K24*(1-N($G24)),2)) -> 7222.6 | M24: =IF($D24="","",IFERROR(INDEX(Items!$F$5:$F$504,U24),0)) -> 0.12 | N24: =IF($D24="","",IF(AND(V24<>"",INDEX(Parties!$E$5:$E$304,V24)<>"",INDEX(Parties!$E$5:$E$304,V24)<>HomeState),0,ROUND(L24*M24/2,2))) -> 0 | O24: =IF($D24="","",N24) -> 0 | P24: =IF($D24="","",IF(AND(V24<>"",INDEX(Parties!$E$5:$E$304,V24)<>"",INDEX(Parties!$E$5:$E$304,V24)<>HomeState),ROUND(L24*M24,2),0)) -> 866.71 | Q24: =IF($D24="","",L24+N24+O24+P24) -> 8089.31 | R24: =IF($D24="","",ROUND(N($E24)*IFERROR(INDEX(Items!$P$5:$P$504,U24),0),2)) -> 5280 | S24: =IF($D24="","",L24-R24) -> 1942.6 | T24: =IF($D24="","",IF(U24="","UNKNOWN ITEM",IF(INDEX(Items!$O$5:$O$504,U24)<0,"NEG STOCK",IF(K24<INDEX(Items!$P$5:$P$504,U24),"BELOW COST","OK")))) -> OK | U24: =IF($D24="","",IFERROR(MATCH($D24,Items!$A$5:$A$504,0),"")) -> 11 | V24: =IF($C24="","",IFERROR(MATCH($C24,Parties!$A$5:$A$304,0),"")) -> 3 | W24: =IF($B24="","",IFERROR(VALUE(SUBSTITUTE($B24,InvPrefix,"")),0)) -> 16 | X24: =IF($D24="","",IF(OR($H24="",$H24="Credit"),0,Q24)) -> 8089.31
A25: 46136 | B25: INV-0016 | C25: Delhi Hardware Mart | D25: Ceiling Fan 1200mm | E25: 4 | G25: 0.05 | H25: Bank | I25: Delivered | J25: =IF($D25="","",IFERROR(INDEX(Items!$D$5:$D$504,U25),"")) -> Pcs | K25: =IF($D25="","",IF($F25="",IFERROR(INDEX(Items!$H$5:$H$504,U25),0),$F25)) -> 2322 | L25: =IF($D25="","",ROUND(N($E25)*K25*(1-N($G25)),2)) -> 8823.6 | M25: =IF($D25="","",IFERROR(INDEX(Items!$F$5:$F$504,U25),0)) -> 0.18 | N25: =IF($D25="","",IF(AND(V25<>"",INDEX(Parties!$E$5:$E$304,V25)<>"",INDEX(Parties!$E$5:$E$304,V25)<>HomeState),0,ROUND(L25*M25/2,2))) -> 0 | O25: =IF($D25="","",N25) -> 0 | P25: =IF($D25="","",IF(AND(V25<>"",INDEX(Parties!$E$5:$E$304,V25)<>"",INDEX(Parties!$E$5:$E$304,V25)<>HomeState),ROUND(L25*M25,2),0)) -> 1588.25 | Q25: =IF($D25="","",L25+N25+O25+P25) -> 10411.85 | R25: =IF($D25="","",ROUND(N($E25)*IFERROR(INDEX(Items!$P$5:$P$504,U25),0),2)) -> 6575.2 | S25: =IF($D25="","",L25-R25) -> 2248.4 | T25: =IF($D25="","",IF(U25="","UNKNOWN ITEM",IF(INDEX(Items!$O$5:$O$504,U25)<0,"NEG STOCK",IF(K25<INDEX(Items!$P$5:$P$504,U25),"BELOW COST","OK")))) -> OK | U25: =IF($D25="","",IFERROR(MATCH($D25,Items!$A$5:$A$504,0),"")) -> 12 | V25: =IF($C25="","",IFERROR(MATCH($C25,Parties!$A$5:$A$304,0),"")) -> 3 | W25: =IF($B25="","",IFERROR(VALUE(SUBSTITUTE($B25,InvPrefix,"")),0)) -> 16 | X25: =IF($D25="","",IF(OR($H25="",$H25="Credit"),0,Q25)) -> 10411.85
A26: 46137 | B26: INV-0017 | C26: Walk-in Customer | D26: LED Bulb 9W | E26: 40 | G26: 0.02 | H26: Cash | I26: Delivered | J26: =IF($D26="","",IFERROR(INDEX(Items!$D$5:$D$504,U26),"")) -> Pcs | K26: =IF($D26="","",IF($F26="",IFERROR(INDEX(Items!$H$5:$H$504,U26),0),$F26)) -> 107 | L26: =IF($D26="","",ROUND(N($E26)*K26*(1-N($G26)),2)) -> 4194.4 | M26: =IF($D26="","",IFERROR(INDEX(Items!$F$5:$F$504,U26),0)) -> 0.18 | N26: =IF($D26="","",IF(AND(V26<>"",INDEX(Parties!$E$5:$E$304,V26)<>"",INDEX(Parties!$E$5:$E$304,V26)<>HomeState),0,ROUND(L26*M26/2,2))) -> 377.5 | O26: =IF($D26="","",N26) -> 377.5 | P26: =IF($D26="","",IF(AND(V26<>"",INDEX(Parties!$E$5:$E$304,V26)<>"",INDEX(Parties!$E$5:$E$304,V26)<>HomeState),ROUND(L26*M26,2),0)) -> 0 | Q26: =IF($D26="","",L26+N26+O26+P26) -> 4949.4 | R26: =IF($D26="","",ROUND(N($E26)*IFERROR(INDEX(Items!$P$5:$P$504,U26),0),2)) -> 2456.68 | S26: =IF($D26="","",L26-R26) -> 1737.72 | T26: =IF($D26="","",IF(U26="","UNKNOWN ITEM",IF(INDEX(Items!$O$5:$O$504,U26)<0,"NEG STOCK",IF(K26<INDEX(Items!$P$5:$P$504,U26),"BELOW COST","OK")))) -> OK | U26: =IF($D26="","",IFERROR(MATCH($D26,Items!$A$5:$A$504,0),"")) -> 7 | V26: =IF($C26="","",IFERROR(MATCH($C26,Parties!$A$5:$A$304,0),"")) -> 4 | W26: =IF($B26="","",IFERROR(VALUE(SUBSTITUTE($B26,InvPrefix,"")),0)) -> 17 | X26: =IF($D26="","",IF(OR($H26="",$H26="Credit"),0,Q26)) -> 4949.4
A27: 46140 | B27: INV-0018 | C27: Gupta Electricals | D27: Refined Oil 15L | E27: 4 | G27: 0.05 | I27: Delivered | J27: =IF($D27="","",IFERROR(INDEX(Items!$D$5:$D$504,U27),"")) -> Box | K27: =IF($D27="","",IF($F27="",IFERROR(INDEX(Items!$H$5:$H$504,U27),0),$F27)) -> 2290 | L27: =IF($D27="","",ROUND(N($E27)*K27*(1-N($G27)),2)) -> 8702 | M27: =IF($D27="","",IFERROR(INDEX(Items!$F$5:$F$504,U27),0)) -> 0.05 | N27: =IF($D27="","",IF(AND(V27<>"",INDEX(Parties!$E$5:$E$304,V27)<>"",INDEX(Parties!$E$5:$E$304,V27)<>HomeState),0,ROUND(L27*M27/2,2))) -> 217.55 | O27: =IF($D27="","",N27) -> 217.55 | P27: =IF($D27="","",IF(AND(V27<>"",INDEX(Parties!$E$5:$E$304,V27)<>"",INDEX(Parties!$E$5:$E$304,V27)<>HomeState),ROUND(L27*M27,2),0)) -> 0 | Q27: =IF($D27="","",L27+N27+O27+P27) -> 9137.1 | R27: =IF($D27="","",ROUND(N($E27)*IFERROR(INDEX(Items!$P$5:$P$504,U27),0),2)) -> 7617.45 | S27: =IF($D27="","",L27-R27) -> 1084.55 | T27: =IF($D27="","",IF(U27="","UNKNOWN ITEM",IF(INDEX(Items!$O$5:$O$504,U27)<0,"NEG STOCK",IF(K27<INDEX(Items!$P$5:$P$504,U27),"BELOW COST","OK")))) -> OK | U27: =IF($D27="","",IFERROR(MATCH($D27,Items!$A$5:$A$504,0),"")) -> 3 | V27: =IF($C27="","",IFERROR(MATCH($C27,Parties!$A$5:$A$304,0),"")) -> 2 | W27: =IF($B27="","",IFERROR(VALUE(SUBSTITUTE($B27,InvPrefix,"")),0)) -> 18 | X27: =IF($D27="","",IF(OR($H27="",$H27="Credit"),0,Q27)) -> 0
A28: 46143 | B28: INV-0019 | C28: Gupta Electricals | D28: Copper Wire 90m | E28: 3 | I28: Delivered | J28: =IF($D28="","",IFERROR(INDEX(Items!$D$5:$D$504,U28),"")) -> Pcs | K28: =IF($D28="","",IF($F28="",IFERROR(INDEX(Items!$H$5:$H$504,U28),0),$F28)) -> 3132 | L28: =IF($D28="","",ROUND(N($E28)*K28*(1-N($G28)),2)) -> 9396 | M28: =IF($D28="","",IFERROR(INDEX(Items!$F$5:$F$504,U28),0)) -> 0.18 | N28: =IF($D28="","",IF(AND(V28<>"",INDEX(Parties!$E$5:$E$304,V28)<>"",INDEX(Parties!$E$5:$E$304,V28)<>HomeState),0,ROUND(L28*M28/2,2))) -> 845.64 | O28: =IF($D28="","",N28) -> 845.64 | P28: =IF($D28="","",IF(AND(V28<>"",INDEX(Parties!$E$5:$E$304,V28)<>"",INDEX(Parties!$E$5:$E$304,V28)<>HomeState),ROUND(L28*M28,2),0)) -> 0 | Q28: =IF($D28="","",L28+N28+O28+P28) -> 11087.28 | R28: =IF($D28="","",ROUND(N($E28)*IFERROR(INDEX(Items!$P$5:$P$504,U28),0),2)) -> 7354.45 | S28: =IF($D28="","",L28-R28) -> 2041.55 | T28: =IF($D28="","",IF(U28="","UNKNOWN ITEM",IF(INDEX(Items!$O$5:$O$504,U28)<0,"NEG STOCK",IF(K28<INDEX(Items!$P$5:$P$504,U28),"BELOW COST","OK")))) -> OK | U28: =IF($D28="","",IFERROR(MATCH($D28,Items!$A$5:$A$504,0),"")) -> 8 | V28: =IF($C28="","",IFERROR(MATCH($C28,Parties!$A$5:$A$304,0),"")) -> 2 | W28: =IF($B28="","",IFERROR(VALUE(SUBSTITUTE($B28,InvPrefix,"")),0)) -> 19 | X28: =IF($D28="","",IF(OR($H28="",$H28="Credit"),0,Q28)) -> 0
A29: 46146 | B29: INV-0020 | C29: Gupta Electricals | D29: Detergent 5kg | E29: 12 | I29: Delivered | J29: =IF($D29="","",IFERROR(INDEX(Items!$D$5:$D$504,U29),"")) -> Pack | K29: =IF($D29="","",IF($F29="",IFERROR(INDEX(Items!$H$5:$H$504,U29),0),$F29)) -> 691 | L29: =IF($D29="","",ROUND(N($E29)*K29*(1-N($G29)),2)) -> 8292 | M29: =IF($D29="","",IFERROR(INDEX(Items!$F$5:$F$504,U29),0)) -> 0.18 | N29: =IF($D29="","",IF(AND(V29<>"",INDEX(Parties!$E$5:$E$304,V29)<>"",INDEX(Parties!$E$5:$E$304,V29)<>HomeState),0,ROUND(L29*M29/2,2))) -> 746.28 | O29: =IF($D29="","",N29) -> 746.28 | P29: =IF($D29="","",IF(AND(V29<>"",INDEX(Parties!$E$5:$E$304,V29)<>"",INDEX(Parties!$E$5:$E$304,V29)<>HomeState),ROUND(L29*M29,2),0)) -> 0 | Q29: =IF($D29="","",L29+N29+O29+P29) -> 9784.56 | R29: =IF($D29="","",ROUND(N($E29)*IFERROR(INDEX(Items!$P$5:$P$504,U29),0),2)) -> 6212.31 | S29: =IF($D29="","",L29-R29) -> 2079.69 | T29: =IF($D29="","",IF(U29="","UNKNOWN ITEM",IF(INDEX(Items!$O$5:$O$504,U29)<0,"NEG STOCK",IF(K29<INDEX(Items!$P$5:$P$504,U29),"BELOW COST","OK")))) -> OK | U29: =IF($D29="","",IFERROR(MATCH($D29,Items!$A$5:$A$504,0),"")) -> 5 | V29: =IF($C29="","",IFERROR(MATCH($C29,Parties!$A$5:$A$304,0),"")) -> 2 | W29: =IF($B29="","",IFERROR(VALUE(SUBSTITUTE($B29,InvPrefix,"")),0)) -> 20 | X29: =IF($D29="","",IF(OR($H29="",$H29="Credit"),0,Q29)) -> 0
A30: 46146 | B30: INV-0020 | C30: Gupta Electricals | D30: Copper Wire 90m | E30: 3 | I30: Delivered | J30: =IF($D30="","",IFERROR(INDEX(Items!$D$5:$D$504,U30),"")) -> Pcs | K30: =IF($D30="","",IF($F30="",IFERROR(INDEX(Items!$H$5:$H$504,U30),0),$F30)) -> 3132 | L30: =IF($D30="","",ROUND(N($E30)*K30*(1-N($G30)),2)) -> 9396 | M30: =IF($D30="","",IFERROR(INDEX(Items!$F$5:$F$504,U30),0)) -> 0.18 | N30: =IF($D30="","",IF(AND(V30<>"",INDEX(Parties!$E$5:$E$304,V30)<>"",INDEX(Parties!$E$5:$E$304,V30)<>HomeState),0,ROUND(L30*M30/2,2))) -> 845.64 | O30: =IF($D30="","",N30) -> 845.64 | P30: =IF($D30="","",IF(AND(V30<>"",INDEX(Parties!$E$5:$E$304,V30)<>"",INDEX(Parties!$E$5:$E$304,V30)<>HomeState),ROUND(L30*M30,2),0)) -> 0 | Q30: =IF($D30="","",L30+N30+O30+P30) -> 11087.28 | R30: =IF($D30="","",ROUND(N($E30)*IFERROR(INDEX(Items!$P$5:$P$504,U30),0),2)) -> 7354.45 | S30: =IF($D30="","",L30-R30) -> 2041.55 | T30: =IF($D30="","",IF(U30="","UNKNOWN ITEM",IF(INDEX(Items!$O$5:$O$504,U30)<0,"NEG STOCK",IF(K30<INDEX(Items!$P$5:$P$504,U30),"BELOW COST","OK")))) -> OK | U30: =IF($D30="","",IFERROR(MATCH($D30,Items!$A$5:$A$504,0),"")) -> 8 | V30: =IF($C30="","",IFERROR(MATCH($C30,Parties!$A$5:$A$304,0),"")) -> 2 | W30: =IF($B30="","",IFERROR(VALUE(SUBSTITUTE($B30,InvPrefix,"")),0)) -> 20 | X30: =IF($D30="","",IF(OR($H30="",$H30="Credit"),0,Q30)) -> 0
A31: 46147 | B31: INV-0021 | C31: Delhi Hardware Mart | D31: PVC Pipe 1in 6m | E31: 20 | H31: Bank | I31: Delivered | J31: =IF($D31="","",IFERROR(INDEX(Items!$D$5:$D$504,U31),"")) -> Pcs | K31: =IF($D31="","",IF($F31="",IFERROR(INDEX(Items!$H$5:$H$504,U31),0),$F31)) -> 297 | L31: =IF($D31="","",ROUND(N($E31)*K31*(1-N($G31)),2)) -> 5940 | M31: =IF($D31="","",IFERROR(INDEX(Items!$F$5:$F$504,U31),0)) -> 0.18 | N31: =IF($D31="","",IF(AND(V31<>"",INDEX(Parties!$E$5:$E$304,V31)<>"",INDEX(Parties!$E$5:$E$304,V31)<>HomeState),0,ROUND(L31*M31/2,2))) -> 0 | O31: =IF($D31="","",N31) -> 0 | P31: =IF($D31="","",IF(AND(V31<>"",INDEX(Parties!$E$5:$E$304,V31)<>"",INDEX(Parties!$E$5:$E$304,V31)<>HomeState),ROUND(L31*M31,2),0)) -> 1069.2 | Q31: =IF($D31="","",L31+N31+O31+P31) -> 7009.2 | R31: =IF($D31="","",ROUND(N($E31)*IFERROR(INDEX(Items!$P$5:$P$504,U31),0),2)) -> 4192.67 | S31: =IF($D31="","",L31-R31) -> 1747.33 | T31: =IF($D31="","",IF(U31="","UNKNOWN ITEM",IF(INDEX(Items!$O$5:$O$504,U31)<0,"NEG STOCK",IF(K31<INDEX(Items!$P$5:$P$504,U31),"BELOW COST","OK")))) -> OK | U31: =IF($D31="","",IFERROR(MATCH($D31,Items!$A$5:$A$504,0),"")) -> 9 | V31: =IF($C31="","",IFERROR(MATCH($C31,Parties!$A$5:$A$304,0),"")) -> 3 | W31: =IF($B31="","",IFERROR(VALUE(SUBSTITUTE($B31,InvPrefix,"")),0)) -> 21 | X31: =IF($D31="","",IF(OR($H31="",$H31="Credit"),0,Q31)) -> 7009.2
A32: 46148 | B32: INV-0022 | C32: Delhi Hardware Mart | D32: PVC Pipe 1in 6m | E32: 25 | G32: 0.05 | I32: Delivered | J32: =IF($D32="","",IFERROR(INDEX(Items!$D$5:$D$504,U32),"")) -> Pcs | K32: =IF($D32="","",IF($F32="",IFERROR(INDEX(Items!$H$5:$H$504,U32),0),$F32)) -> 297 | L32: =IF($D32="","",ROUND(N($E32)*K32*(1-N($G32)),2)) -> 7053.75 | M32: =IF($D32="","",IFERROR(INDEX(Items!$F$5:$F$504,U32),0)) -> 0.18 | N32: =IF($D32="","",IF(AND(V32<>"",INDEX(Parties!$E$5:$E$304,V32)<>"",INDEX(Parties!$E$5:$E$304,V32)<>HomeState),0,ROUND(L32*M32/2,2))) -> 0 | O32: =IF($D32="","",N32) -> 0 | P32: =IF($D32="","",IF(AND(V32<>"",INDEX(Parties!$E$5:$E$304,V32)<>"",INDEX(Parties!$E$5:$E$304,V32)<>HomeState),ROUND(L32*M32,2),0)) -> 1269.68 | Q32: =IF($D32="","",L32+N32+O32+P32) -> 8323.43 | R32: =IF($D32="","",ROUND(N($E32)*IFERROR(INDEX(Items!$P$5:$P$504,U32),0),2)) -> 5240.83 | S32: =IF($D32="","",L32-R32) -> 1812.92 | T32: =IF($D32="","",IF(U32="","UNKNOWN ITEM",IF(INDEX(Items!$O$5:$O$504,U32)<0,"NEG STOCK",IF(K32<INDEX(Items!$P$5:$P$504,U32),"BELOW COST","OK")))) -> OK | U32: =IF($D32="","",IFERROR(MATCH($D32,Items!$A$5:$A$504,0),"")) -> 9 | V32: =IF($C32="","",IFERROR(MATCH($C32,Parties!$A$5:$A$304,0),"")) -> 3 | W32: =IF($B32="","",IFERROR(VALUE(SUBSTITUTE($B32,InvPrefix,"")),0)) -> 22 | X32: =IF($D32="","",IF(OR($H32="",$H32="Credit"),0,Q32)) -> 0
A33: 46149 | B33: INV-0023 | C33: Walk-in Customer | D33: Tea Premium 1kg | E33: 16 | H33: Cash | I33: Delivered | J33: =IF($D33="","",IFERROR(INDEX(Items!$D$5:$D$504,U33),"")) -> Pack | K33: =IF($D33="","",IF($F33="",IFERROR(INDEX(Items!$H$5:$H$504,U33),0),$F33)) -> 508 | L33: =IF($D33="","",ROUND(N($E33)*K33*(1-N($G33)),2)) -> 8128 | M33: =IF($D33="","",IFERROR(INDEX(Items!$F$5:$F$504,U33),0)) -> 0.05 | N33: =IF($D33="","",IF(AND(V33<>"",INDEX(Parties!$E$5:$E$304,V33)<>"",INDEX(Parties!$E$5:$E$304,V33)<>HomeState),0,ROUND(L33*M33/2,2))) -> 203.2 | O33: =IF($D33="","",N33) -> 203.2 | P33: =IF($D33="","",IF(AND(V33<>"",INDEX(Parties!$E$5:$E$304,V33)<>"",INDEX(Parties!$E$5:$E$304,V33)<>HomeState),ROUND(L33*M33,2),0)) -> 0 | Q33: =IF($D33="","",L33+N33+O33+P33) -> 8534.4 | R33: =IF($D33="","",ROUND(N($E33)*IFERROR(INDEX(Items!$P$5:$P$504,U33),0),2)) -> 6033.27 | S33: =IF($D33="","",L33-R33) -> 2094.73 | T33: =IF($D33="","",IF(U33="","UNKNOWN ITEM",IF(INDEX(Items!$O$5:$O$504,U33)<0,"NEG STOCK",IF(K33<INDEX(Items!$P$5:$P$504,U33),"BELOW COST","OK")))) -> OK | U33: =IF($D33="","",IFERROR(MATCH($D33,Items!$A$5:$A$504,0),"")) -> 4 | V33: =IF($C33="","",IFERROR(MATCH($C33,Parties!$A$5:$A$304,0),"")) -> 4 | W33: =IF($B33="","",IFERROR(VALUE(SUBSTITUTE($B33,InvPrefix,"")),0)) -> 23 | X33: =IF($D33="","",IF(OR($H33="",$H33="Credit"),0,Q33)) -> 8534.4
A34: 46149 | B34: INV-0023 | C34: Walk-in Customer | D34: Ceiling Fan 1200mm | E34: 2 | G34: 0.02 | H34: Cash | I34: Delivered | J34: =IF($D34="","",IFERROR(INDEX(Items!$D$5:$D$504,U34),"")) -> Pcs | K34: =IF($D34="","",IF($F34="",IFERROR(INDEX(Items!$H$5:$H$504,U34),0),$F34)) -> 2322 | L34: =IF($D34="","",ROUND(N($E34)*K34*(1-N($G34)),2)) -> 4551.12 | M34: =IF($D34="","",IFERROR(INDEX(Items!$F$5:$F$504,U34),0)) -> 0.18 | N34: =IF($D34="","",IF(AND(V34<>"",INDEX(Parties!$E$5:$E$304,V34)<>"",INDEX(Parties!$E$5:$E$304,V34)<>HomeState),0,ROUND(L34*M34/2,2))) -> 409.6 | O34: =IF($D34="","",N34) -> 409.6 | P34: =IF($D34="","",IF(AND(V34<>"",INDEX(Parties!$E$5:$E$304,V34)<>"",INDEX(Parties!$E$5:$E$304,V34)<>HomeState),ROUND(L34*M34,2),0)) -> 0 | Q34: =IF($D34="","",L34+N34+O34+P34) -> 5370.32 | R34: =IF($D34="","",ROUND(N($E34)*IFERROR(INDEX(Items!$P$5:$P$504,U34),0),2)) -> 3287.6 | S34: =IF($D34="","",L34-R34) -> 1263.52 | T34: =IF($D34="","",IF(U34="","UNKNOWN ITEM",IF(INDEX(Items!$O$5:$O$504,U34)<0,"NEG STOCK",IF(K34<INDEX(Items!$P$5:$P$504,U34),"BELOW COST","OK")))) -> OK | U34: =IF($D34="","",IFERROR(MATCH($D34,Items!$A$5:$A$504,0),"")) -> 12 | V34: =IF($C34="","",IFERROR(MATCH($C34,Parties!$A$5:$A$304,0),"")) -> 4 | W34: =IF($B34="","",IFERROR(VALUE(SUBSTITUTE($B34,InvPrefix,"")),0)) -> 23 | X34: =IF($D34="","",IF(OR($H34="",$H34="Credit"),0,Q34)) -> 5370.32
A35: 46150 | B35: INV-0024 | C35: Sharma Kirana Store | D35: Copper Wire 90m | E35: 2 | G35: 0.05 | I35: Delivered | J35: =IF($D35="","",IFERROR(INDEX(Items!$D$5:$D$504,U35),"")) -> Pcs | K35: =IF($D35="","",IF($F35="",IFERROR(INDEX(Items!$H$5:$H$504,U35),0),$F35)) -> 3132 | L35: =IF($D35="","",ROUND(N($E35)*K35*(1-N($G35)),2)) -> 5950.8 | M35: =IF($D35="","",IFERROR(INDEX(Items!$F$5:$F$504,U35),0)) -> 0.18 | N35: =IF($D35="","",IF(AND(V35<>"",INDEX(Parties!$E$5:$E$304,V35)<>"",INDEX(Parties!$E$5:$E$304,V35)<>HomeState),0,ROUND(L35*M35/2,2))) -> 535.57 | O35: =IF($D35="","",N35) -> 535.57 | P35: =IF($D35="","",IF(AND(V35<>"",INDEX(Parties!$E$5:$E$304,V35)<>"",INDEX(Parties!$E$5:$E$304,V35)<>HomeState),ROUND(L35*M35,2),0)) -> 0 | Q35: =IF($D35="","",L35+N35+O35+P35) -> 7021.94 | R35: =IF($D35="","",ROUND(N($E35)*IFERROR(INDEX(Items!$P$5:$P$504,U35),0),2)) -> 4902.96 | S35: =IF($D35="","",L35-R35) -> 1047.84 | T35: =IF($D35="","",IF(U35="","UNKNOWN ITEM",IF(INDEX(Items!$O$5:$O$504,U35)<0,"NEG STOCK",IF(K35<INDEX(Items!$P$5:$P$504,U35),"BELOW COST","OK")))) -> OK | U35: =IF($D35="","",IFERROR(MATCH($D35,Items!$A$5:$A$504,0),"")) -> 8 | V35: =IF($C35="","",IFERROR(MATCH($C35,Parties!$A$5:$A$304,0),"")) -> 1 | W35: =IF($B35="","",IFERROR(VALUE(SUBSTITUTE($B35,InvPrefix,"")),0)) -> 24 | X35: =IF($D35="","",IF(OR($H35="",$H35="Credit"),0,Q35)) -> 0
A36: 46151 | B36: INV-0025 | C36: Walk-in Customer | D36: Toothpaste 150g x12 | E36: 3 | H36: Cash | I36: Delivered | J36: =IF($D36="","",IFERROR(INDEX(Items!$D$5:$D$504,U36),"")) -> Box | K36: =IF($D36="","",IF($F36="",IFERROR(INDEX(Items!$H$5:$H$504,U36),0),$F36)) -> 1166 | L36: =IF($D36="","",ROUND(N($E36)*K36*(1-N($G36)),2)) -> 3498 | M36: =IF($D36="","",IFERROR(INDEX(Items!$F$5:$F$504,U36),0)) -> 0.05 | N36: =IF($D36="","",IF(AND(V36<>"",INDEX(Parties!$E$5:$E$304,V36)<>"",INDEX(Parties!$E$5:$E$304,V36)<>HomeState),0,ROUND(L36*M36/2,2))) -> 87.45 | O36: =IF($D36="","",N36) -> 87.45 | P36: =IF($D36="","",IF(AND(V36<>"",INDEX(Parties!$E$5:$E$304,V36)<>"",INDEX(Parties!$E$5:$E$304,V36)<>HomeState),ROUND(L36*M36,2),0)) -> 0 | Q36: =IF($D36="","",L36+N36+O36+P36) -> 3672.9 | R36: =IF($D36="","",ROUND(N($E36)*IFERROR(INDEX(Items!$P$5:$P$504,U36),0),2)) -> 2665.44 | S36: =IF($D36="","",L36-R36) -> 832.56 | T36: =IF($D36="","",IF(U36="","UNKNOWN ITEM",IF(INDEX(Items!$O$5:$O$504,U36)<0,"NEG STOCK",IF(K36<INDEX(Items!$P$5:$P$504,U36),"BELOW COST","OK")))) -> OK | U36: =IF($D36="","",IFERROR(MATCH($D36,Items!$A$5:$A$504,0),"")) -> 6 | V36: =IF($C36="","",IFERROR(MATCH($C36,Parties!$A$5:$A$304,0),"")) -> 4 | W36: =IF($B36="","",IFERROR(VALUE(SUBSTITUTE($B36,InvPrefix,"")),0)) -> 25 | X36: =IF($D36="","",IF(OR($H36="",$H36="Credit"),0,Q36)) -> 3672.9
A37: 46151 | B37: INV-0025 | C37: Walk-in Customer | D37: Ceiling Fan 1200mm | E37: 2 | H37: Cash | I37: Delivered | J37: =IF($D37="","",IFERROR(INDEX(Items!$D$5:$D$504,U37),"")) -> Pcs | K37: =IF($D37="","",IF($F37="",IFERROR(INDEX(Items!$H$5:$H$504,U37),0),$F37)) -> 2322 | L37: =IF($D37="","",ROUND(N($E37)*K37*(1-N($G37)),2)) -> 4644 | M37: =IF($D37="","",IFERROR(INDEX(Items!$F$5:$F$504,U37),0)) -> 0.18 | N37: =IF($D37="","",IF(AND(V37<>"",INDEX(Parties!$E$5:$E$304,V37)<>"",INDEX(Parties!$E$5:$E$304,V37)<>HomeState),0,ROUND(L37*M37/2,2))) -> 417.96 | O37: =IF($D37="","",N37) -> 417.96 | P37: =IF($D37="","",IF(AND(V37<>"",INDEX(Parties!$E$5:$E$304,V37)<>"",INDEX(Parties!$E$5:$E$304,V37)<>HomeState),ROUND(L37*M37,2),0)) -> 0 | Q37: =IF($D37="","",L37+N37+O37+P37) -> 5479.92 | R37: =IF($D37="","",ROUND(N($E37)*IFERROR(INDEX(Items!$P$5:$P$504,U37),0),2)) -> 3287.6 | S37: =IF($D37="","",L37-R37) -> 1356.4 | T37: =IF($D37="","",IF(U37="","UNKNOWN ITEM",IF(INDEX(Items!$O$5:$O$504,U37)<0,"NEG STOCK",IF(K37<INDEX(Items!$P$5:$P$504,U37),"BELOW COST","OK")))) -> OK | U37: =IF($D37="","",IFERROR(MATCH($D37,Items!$A$5:$A$504,0),"")) -> 12 | V37: =IF($C37="","",IFERROR(MATCH($C37,Parties!$A$5:$A$304,0),"")) -> 4 | W37: =IF($B37="","",IFERROR(VALUE(SUBSTITUTE($B37,InvPrefix,"")),0)) -> 25 | X37: =IF($D37="","",IF(OR($H37="",$H37="Credit"),0,Q37)) -> 5479.92
