Workbook
Name CoName: Settings!$B$4
Name CoAddr: Settings!$B$5
Name CoGSTIN: Settings!$B$6
Name HomeState: Settings!$B$7
Name CoPhone: Settings!$B$8
Name FYStart: Settings!$B$9
Name AsOf: Settings!$B$10
Name InvPrefix: Settings!$B$11
Name DeadDays: Settings!$B$12
Name CoBank: Settings!$B$13
Name L_Categories: OFFSET(Settings!$D$5,0,0,MAX(1,COUNTA(Settings!$D$5:$D$44)),1)
Name L_Units: OFFSET(Settings!$E$5,0,0,MAX(1,COUNTA(Settings!$E$5:$E$44)),1)
Name L_GSTRates: OFFSET(Settings!$F$5,0,0,MAX(1,COUNTA(Settings!$F$5:$F$44)),1)
Name L_PayModes: OFFSET(Settings!$G$5,0,0,MAX(1,COUNTA(Settings!$G$5:$G$44)),1)
Name L_VoucherTypes: OFFSET(Settings!$H$5,0,0,MAX(1,COUNTA(Settings!$H$5:$H$44)),1)
Name L_ExpenseHeads: OFFSET(Settings!$I$5,0,0,MAX(1,COUNTA(Settings!$I$5:$I$44)),1)
Name L_PartyTypes: OFFSET(Settings!$J$5,0,0,MAX(1,COUNTA(Settings!$J$5:$J$44)),1)
Name L_DeliveryStatus: OFFSET(Settings!$K$5,0,0,MAX(1,COUNTA(Settings!$K$5:$K$44)),1)
Name L_AdjReasons: OFFSET(Settings!$L$5,0,0,MAX(1,COUNTA(Settings!$L$5:$L$44)),1)
Name L_States: OFFSET(Settings!$M$5,0,0,MAX(1,COUNTA(Settings!$M$5:$M$44)),1)
Name L_Accounts: OFFSET(Settings!$A$18,0,0,MAX(1,COUNTA(Settings!$A$18:$A$25)),1)
Name L_Items: OFFSET(Items!$A$5,0,0,MAX(1,COUNTA(Items!$A$5:$A$2004)),1)
Name L_Parties: OFFSET(Parties!$A$5,0,0,MAX(1,COUNTA(Parties!$A$5:$A$1004)),1)
Name DFrom: Dashboard!$D$4
Name DTo: Dashboard!$G$4
Name IN_Items: Items!$A$5:$K$2004
Name IN_Parties: Parties!$A$5:$I$1004
Name IN_Purchases: Purchases!$A$5:$H$20004
Name IN_Sales: Sales!$A$5:$I$20004
Name IN_CashBook: CashBook!$A$5:$H$20004
Name IN_Adjust: Adjustments!$A$5:$E$2004
Name IN_Settings: Settings!$B$4:$B$13

Sheet Dashboard
B1: =CoName&" · SmartTrader ERP (C Engine)"
B2: ="Live business cockpit · Period: "&TEXT(D4,"dd-mmm-yy")&" to "&TEXT(G4,"dd-mmm-yy")
B4: From | D4: =FYStart | E4: To | G4: =AsOf | H4: ← overwrite these dates to analyse any period | K4: =IFERROR("✔ "&_xll.ST_VERSION(),"⚠ C engine not loaded - see Guide")
B6: ➕ New Sale | C6: 🛒 Purchase | D6: 💰 Cash Book | E6: 📦 Items | F6: 👥 Parties | G6: 🧾 Invoice | H6: 🔧 Adjust | I6: 📊 Reports | J6: ⚙ Settings | K6: ❓ Guide
B8: SALES (excl. GST) | D8: GROSS PROFIT | F8: NET PROFIT | H8: PURCHASES (excl. GST) | J8: EXPENSES
B9: =SUMIFS(Sales!$L$5:$L$20004,Sales!$A$5:$A$20004,">="&DFrom,Sales!$A$5:$A$20004,"<="&DTo) | D9: =SUMIFS(Sales!$S$5:$S$20004,Sales!$A$5:$A$20004,">="&DFrom,Sales!$A$5:$A$20004,"<="&DTo) | F9: =D9-SUMIFS(CashBook!$G$5:$G$20004,CashBook!$C$5:$C$20004,"Expense",CashBook!$A$5:$A$20004,">="&DFrom,CashBook!$A$5:$A$20004,"<="&DTo)+SUMIFS(CashBook!$G$5:$G$20004,CashBook!$C$5:$C$20004,"Other Income",CashBook!$A$5:$A$20004,">="&DFrom,CashBook!$A$5:$A$20004,"<="&DTo)+SUMIFS(Adjustments!$G$5:$G$2004,Adjustments!$A$5:$A$2004,">="&DFrom,Adjustments!$A$5:$A$2004,"<="&DTo) | H9: =SUMIFS(Purchases!$K$5:$K$20004,Purchases!$A$5:$A$20004,">="&DFrom,Purchases!$A$5:$A$20004,"<="&DTo) | J9: =SUMIFS(CashBook!$G$5:$G$20004,CashBook!$C$5:$C$20004,"Expense",CashBook!$A$5:$A$20004,">="&DFrom,CashBook!$A$5:$A$20004,"<="&DTo)
B11: GP MARGIN | D11: RECEIVABLES (owed to you) | F11: PAYABLES (you owe) | H11: STOCK VALUE (at cost) | J11: NET GST PAYABLE
B12: =IF(B9=0,0,D9/B9) | D12: =SUMIF(Parties!$N$5:$N$1004,">0") | F12: =-SUMIF(Parties!$N$5:$N$1004,"<0") | H12: =SUM(Items!$Q$5:$Q$2004) | J12: =SUMIFS(Sales!$N$5:$N$20004,Sales!$A$5:$A$20004,">="&DFrom,Sales!$A$5:$A$20004,"<="&DTo)+SUMIFS(Sales!$O$5:$O$20004,Sales!$A$5:$A$20004,">="&DFrom,Sales!$A$5:$A$20004,"<="&DTo)+SUMIFS(Sales!$P$5:$P$20004,Sales!$A$5:$A$20004,">="&DFrom,Sales!$A$5:$A$20004,"<="&DTo)-SUMIFS(Purchases!$M$5:$M$20004,Purchases!$A$5:$A$20004,">="&DFrom,Purchases!$A$5:$A$20004,"<="&DTo)-SUMIFS(Purchases!$N$5:$N$20004,Purchases!$A$5:$A$20004,">="&DFrom,Purchases!$A$5:$A$20004,"<="&DTo)-SUMIFS(Purchases!$O$5:$O$20004,Purchases!$A$5:$A$20004,">="&DFrom,Purchases!$A$5:$A$20004,"<="&DTo)
B14: ITEMS TO REORDER | D14: DEAD-STOCK ITEMS | F14: OVERDUE CUSTOMERS | H14: PENDING DELIVERIES (lines) | J14: NEXT INVOICE No.
B15: =COUNTIF(Items!$R$5:$R$2004,"REORDER")+COUNTIF(Items!$R$5:$R$2004,"OUT OF STOCK")+COUNTIF(Items!$R$5:$R$2004,"NEGATIVE") | D15: =COUNTIF(Items!$R$5:$R$2004,"DEAD STOCK") | F15: =COUNTIF(Parties!$S$5:$S$1004,"OVERDUE")+COUNTIF(Parties!$S$5:$S$1004,"OVER LIMIT") | H15: =COUNTIFS(Sales!$I$5:$I$20004,"Pending")+COUNTIFS(Sales!$I$5:$I$20004,"Packed") | J15: =InvPrefix&TEXT(MAX(Sales!$W$5:$W$20004)+1,"0000")
B18: CASH & BANK BALANCES (as of 'To' date) | I18: TOP 10 ITEMS BY SALES (all time)
B19: Account | D19: Opening | E19: In | F19: Out | G19: Balance | I19: # | J19: Item | L19: Sales (₹) | M19: Stock | N19: Status
B20: =IF(Settings!$A$18="","",Settings!$A$18) | D20: =IF(B20="","",N(Settings!$B$18)) | E20: =IF(B20="","",SUMIFS(CashBook!$I$5:$I$20004,CashBook!$F$5:$F$20004,B20,CashBook!$A$5:$A$20004,"<="&DTo)+SUMIFS(Sales!$X$5:$X$20004,Sales!$H$5:$H$20004,B20,Sales!$A$5:$A$20004,"<="&DTo)) | F20: =IF(B20="","",SUMIFS(CashBook!$J$5:$J$20004,CashBook!$F$5:$F$20004,B20,CashBook!$A$5:$A$20004,"<="&DTo)+SUMIFS(Purchases!$S$5:$S$20004,Purchases!$H$5:$H$20004,B20,Purchases!$A$5:$A$20004,"<="&DTo)) | G20: =IF(B20="","",D20+E20-F20) | I20: 1 | J20: =IFERROR(IF(INDEX(Items!$U$5:$U$2004,MATCH(LARGE(Items!$Z$5:$Z$2004,1),Items!$Z$5:$Z$2004,0))=0,"",INDEX(Items!$A$5:$A$2004,MATCH(LARGE(Items!$Z$5:$Z$2004,1),Items!$Z$5:$Z$2004,0))),"") | L20: =IF(J20="","",INDEX(Items!$U$5:$U$2004,MATCH(LARGE(Items!$Z$5:$Z$2004,1),Items!$Z$5:$Z$2004,0))) | M20: =IF(J20="","",INDEX(Items!$O$5:$O$2004,MATCH(LARGE(Items!$Z$5:$Z$2004,1),Items!$Z$5:$Z$2004,0))) | N20: =IF(J20="","",INDEX(Items!$R$5:$R$2004,MATCH(LARGE(Items!$Z$5:$Z$2004,1),Items!$Z$5:$Z$2004,0)))
B21: =IF(Settings!$A$19="","",Settings!$A$19) | D21: =IF(B21="","",N(Settings!$B$19)) | E21: =IF(B21="","",SUMIFS(CashBook!$I$5:$I$20004,CashBook!$F$5:$F$20004,B21,CashBook!$A$5:$A$20004,"<="&DTo)+SUMIFS(Sales!$X$5:$X$20004,Sales!$H$5:$H$20004,B21,Sales!$A$5:$A$20004,"<="&DTo)) | F21: =IF(B21="","",SUMIFS(CashBook!$J$5:$J$20004,CashBook!$F$5:$F$20004,B21,CashBook!$A$5:$A$20004,"<="&DTo)+SUMIFS(Purchases!$S$5:$S$20004,Purchases!$H$5:$H$20004,B21,Purchases!$A$5:$A$20004,"<="&DTo)) | G21: =IF(B21="","",D21+E21-F21) | I21: 2 | J21: =IFERROR(IF(INDEX(Items!$U$5:$U$2004,MATCH(LARGE(Items!$Z$5:$Z$2004,2),Items!$Z$5:$Z$2004,0))=0,"",INDEX(Items!$A$5:$A$2004,MATCH(LARGE(Items!$Z$5:$Z$2004,2),Items!$Z$5:$Z$2004,0))),"") | L21: =IF(J21="","",INDEX(Items!$U$5:$U$2004,MATCH(LARGE(Items!$Z$5:$Z$2004,2),Items!$Z$5:$Z$2004,0))) | M21: =IF(J21="","",INDEX(Items!$O$5:$O$2004,MATCH(LARGE(Items!$Z$5:$Z$2004,2),Items!$Z$5:$Z$2004,0))) | N21: =IF(J21="","",INDEX(Items!$R$5:$R$2004,MATCH(LARGE(Items!$Z$5:$Z$2004,2),Items!$Z$5:$Z$2004,0)))
B22: =IF(Settings!$A$20="","",Settings!$A$20) | D22: =IF(B22="","",N(Settings!$B$20)) | E22: =IF(B22="","",SUMIFS(CashBook!$I$5:$I$20004,CashBook!$F$5:$F$20004,B22,CashBook!$A$5:$A$20004,"<="&DTo)+SUMIFS(Sales!$X$5:$X$20004,Sales!$H$5:$H$20004,B22,Sales!$A$5:$A$20004,"<="&DTo)) | F22: =IF(B22="","",SUMIFS(CashBook!$J$5:$J$20004,CashBook!$F$5:$F$20004,B22,CashBook!$A$5:$A$20004,"<="&DTo)+SUMIFS(Purchases!$S$5:$S$20004,Purchases!$H$5:$H$20004,B22,Purchases!$A$5:$A$20004,"<="&DTo)) | G22: =IF(B22="","",D22+E22-F22) | I22: 3 | J22: =IFERROR(IF(INDEX(Items!$U$5:$U$2004,MATCH(LARGE(Items!$Z$5:$Z$2004,3),Items!$Z$5:$Z$2004,0))=0,"",INDEX(Items!$A$5:$A$2004,MATCH(LARGE(Items!$Z$5:$Z$2004,3),Items!$Z$5:$Z$2004,0))),"") | L22: =IF(J22="","",INDEX(Items!$U$5:$U$2004,MATCH(LARGE(Items!$Z$5:$Z$2004,3),Items!$Z$5:$Z$2004,0))) | M22: =IF(J22="","",INDEX(Items!$O$5:$O$2004,MATCH(LARGE(Items!$Z$5:$Z$2004,3),Items!$Z$5:$Z$2004,0))) | N22: =IF(J22="","",INDEX(Items!$R$5:$R$2004,MATCH(LARGE(Items!$Z$5:$Z$2004,3),Items!$Z$5:$Z$2004,0)))
B23: =IF(Settings!$A$21="","",Settings!$A$21) | D23: =IF(B23="","",N(Settings!$B$21)) | E23: =IF(B23="","",SUMIFS(CashBook!$I$5:$I$20004,CashBook!$F$5:$F$20004,B23,CashBook!$A$5:$A$20004,"<="&DTo)+SUMIFS(Sales!$X$5:$X$20004,Sales!$H$5:$H$20004,B23,Sales!$A$5:$A$20004,"<="&DTo)) | F23: =IF(B23="","",SUMIFS(CashBook!$J$5:$J$20004,CashBook!$F$5:$F$20004,B23,CashBook!$A$5:$A$20004,"<="&DTo)+SUMIFS(Purchases!$S$5:$S$20004,Purchases!$H$5:$H$20004,B23,Purchases!$A$5:$A$20004,"<="&DTo)) | G23: =IF(B23="","",D23+E23-F23) | I23: 4 | J23: =IFERROR(IF(INDEX(Items!$U$5:$U$2004,MATCH(LARGE(Items!$Z$5:$Z$2004,4),Items!$Z$5:$Z$2004,0))=0,"",INDEX(Items!$A$5:$A$2004,MATCH(LARGE(Items!$Z$5:$Z$2004,4),Items!$Z$5:$Z$2004,0))),"") | L23: =IF(J23="","",INDEX(Items!$U$5:$U$2004,MATCH(LARGE(Items!$Z$5:$Z$2004,4),Items!$Z$5:$Z$2004,0))) | M23: =IF(J23="","",INDEX(Items!$O$5:$O$2004,MATCH(LARGE(Items!$Z$5:$Z$2004,4),Items!$Z$5:$Z$2004,0))) | N23: =IF(J23="","",INDEX(Items!$R$5:$R$2004,MATCH(LARGE(Items!$Z$5:$Z$2004,4),Items!$Z$5:$Z$2004,0)))
B24: TOTAL LIQUIDITY | G24: =SUM(G20:G23) | I24: 5 | J24: =IFERROR(IF(INDEX(Items!$U$5:$U$2004,MATCH(LARGE(Items!$Z$5:$Z$2004,5),Items!$Z$5:$Z$2004,0))=0,"",INDEX(Items!$A$5:$A$2004,MATCH(LARGE(Items!$Z$5:$Z$2004,5),Items!$Z$5:$Z$2004,0))),"") | L24: =IF(J24="","",INDEX(Items!$U$5:$U$2004,MATCH(LARGE(Items!$Z$5:$Z$2004,5),Items!$Z$5:$Z$2004,0))) | M24: =IF(J24="","",INDEX(Items!$O$5:$O$2004,MATCH(LARGE(Items!$Z$5:$Z$2004,5),Items!$Z$5:$Z$2004,0))) | N24: =IF(J24="","",INDEX(Items!$R$5:$R$2004,MATCH(LARGE(Items!$Z$5:$Z$2004,5),Items!$Z$5:$Z$2004,0)))
I25: 6 | J25: =IFERROR(IF(INDEX(Items!$U$5:$U$2004,MATCH(LARGE(Items!$Z$5:$Z$2004,6),Items!$Z$5:$Z$2004,0))=0,"",INDEX(Items!$A$5:$A$2004,MATCH(LARGE(Items!$Z$5:$Z$2004,6),Items!$Z$5:$Z$2004,0))),"") | L25: =IF(J25="","",INDEX(Items!$U$5:$U$2004,MATCH(LARGE(Items!$Z$5:$Z$2004,6),Items!$Z$5:$Z$2004,0))) | M25: =IF(J25="","",INDEX(Items!$O$5:$O$2004,MATCH(LARGE(Items!$Z$5:$Z$2004,6),Items!$Z$5:$Z$2004,0))) | N25: =IF(J25="","",INDEX(Items!$R$5:$R$2004,MATCH(LARGE(Items!$Z$5:$Z$2004,6),Items!$Z$5:$Z$2004,0)))
I26: 7 | J26: =IFERROR(IF(INDEX(Items!$U$5:$U$2004,MATCH(LARGE(Items!$Z$5:$Z$2004,7),Items!$Z$5:$Z$2004,0))=0,"",INDEX(Items!$A$5:$A$2004,MATCH(LARGE(Items!$Z$5:$Z$2004,7),Items!$Z$5:$Z$2004,0))),"") | L26: =IF(J26="","",INDEX(Items!$U$5:$U$2004,MATCH(LARGE(Items!$Z$5:$Z$2004,7),Items!$Z$5:$Z$2004,0))) | M26: =IF(J26="","",INDEX(Items!$O$5:$O$2004,MATCH(LARGE(Items!$Z$5:$Z$2004,7),Items!$Z$5:$Z$2004,0))) | N26: =IF(J26="","",INDEX(Items!$R$5:$R$2004,MATCH(LARGE(Items!$Z$5:$Z$2004,7),Items!$Z$5:$Z$2004,0)))
I27: 8 | J27: =IFERROR(IF(INDEX(Items!$U$5:$U$2004,MATCH(LARGE(Items!$Z$5:$Z$2004,8),Items!$Z$5:$Z$2004,0))=0,"",INDEX(Items!$A$5:$A$2004,MATCH(LARGE(Items!$Z$5:$Z$2004,8),Items!$Z$5:$Z$2004,0))),"") | L27: =IF(J27="","",INDEX(Items!$U$5:$U$2004,MATCH(LARGE(Items!$Z$5:$Z$2004,8),Items!$Z$5:$Z$2004,0))) | M27: =IF(J27="","",INDEX(Items!$O$5:$O$2004,MATCH(LARGE(Items!$Z$5:$Z$2004,8),Items!$Z$5:$Z$2004,0))) | N27: =IF(J27="","",INDEX(Items!$R$5:$R$2004,MATCH(LARGE(Items!$Z$5:$Z$2004,8),Items!$Z$5:$Z$2004,0)))
I28: 9 | J28: =IFERROR(IF(INDEX(Items!$U$5:$U$2004,MATCH(LARGE(Items!$Z$5:$Z$2004,9),Items!$Z$5:$Z$2004,0))=0,"",INDEX(Items!$A$5:$A$2004,MATCH(LARGE(Items!$Z$5:$Z$2004,9),Items!$Z$5:$Z$2004,0))),"") | L28: =IF(J28="","",INDEX(Items!$U$5:$U$2004,MATCH(LARGE(Items!$Z$5:$Z$2004,9),Items!$Z$5:$Z$2004,0))) | M28: =IF(J28="","",INDEX(Items!$O$5:$O$2004,MATCH(LARGE(Items!$Z$5:$Z$2004,9),Items!$Z$5:$Z$2004,0))) | N28: =IF(J28="","",INDEX(Items!$R$5:$R$2004,MATCH(LARGE(Items!$Z$5:$Z$2004,9),Items!$Z$5:$Z$2004,0)))
I29: 10 | J29: =IFERROR(IF(INDEX(Items!$U$5:$U$2004,MATCH(LARGE(Items!$Z$5:$Z$2004,10),Items!$Z$5:$Z$2004,0))=0,"",INDEX(Items!$A$5:$A$2004,MATCH(LARGE(Items!$Z$5:$Z$2004,10),Items!$Z$5:$Z$2004,0))),"") | L29: =IF(J29="","",INDEX(Items!$U$5:$U$2004,MATCH(LARGE(Items!$Z$5:$Z$2004,10),Items!$Z$5:$Z$2004,0))) | M29: =IF(J29="","",INDEX(Items!$O$5:$O$2004,MATCH(LARGE(Items!$Z$5:$Z$2004,10),Items!$Z$5:$Z$2004,0))) | N29: =IF(J29="","",INDEX(Items!$R$5:$R$2004,MATCH(LARGE(Items!$Z$5:$Z$2004,10),Items!$Z$5:$Z$2004,0)))

Sheet Sales
A1: 🧾 SALES / INVOICES (DELIVER) | Z1: ◀ Home
A2: One line per item sold. Keep all lines of an invoice together. Leave Rate blank to use the standard sale rate.
A3: Blue / cream = type here | J3: ⚙ C engine: {=_xll.ST_SALES(…)} fills J:X
A4: Date * | B4: Invoice No * | C4: Customer * | D4: Item * | E4: Qty * | F4: Rate (₹) blank=std | G4: Disc % | H4: Paid Via (blank=Credit) | I4: Delivery | J4: Unit | K4: Rate Used (₹) | L4: Taxable (₹) | M4: GST % | N4: CGST (₹) | O4: SGST (₹) | P4: IGST (₹) | Q4: Line Total (₹) | R4: COGS (₹) | S4: Profit (₹) | T4: Stock Check | U4: itemRow | V4: partyRow | W4: invNum | X4: Paid Now (₹)
A5: 46113 | B5: INV-0001 | C5: FMCG Distributors | D5: PVC Pipe 1in 6m | E5: 3 | H5: Bank | I5: Delivered | J5: {=_xll.ST_SALES(IN_Items,IN_Parties,IN_Purchases,IN_Sales,IN_CashBook,IN_Adjust,IN_Settings)}
A6: 46113 | B6: INV-0002 | C6: Walk-in Customer | D6: Sugar 50kg | E6: 1 | H6: Cash | I6: Delivered
A7: 46113 | B7: INV-0002 | C7: Walk-in Customer | D7: Tea Premium 1kg | E7: 4 | H7: Cash | I7: Delivered
A8: 46113 | B8: INV-0002 | C8: Walk-in Customer | D8: Ceiling Fan 1200mm | E8: 1 | G8: 0.05 | H8: Cash | I8: Delivered
A9: 46114 | B9: INV-0003 | C9: Walk-in Customer | D9: Tea Premium 1kg | E9: 1 | H9: Cash | I9: Delivered
A10: 46114 | B10: INV-0004 | C10: Mehta Constructions | D10: PVC Pipe 1in 6m | E10: 6 | G10: 0.05 | H10: UPI | I10: Delivered
A11: 46114 | B11: INV-0004 | C11: Mehta Constructions | D11: Sugar 50kg | E11: 1 | H11: UPI | I11: Delivered
A12: 46115 | B12: INV-0005 | C12: Walk-in Customer | D12: Sugar 50kg | E12: 1 | G12: 0.05 | H12: Cash | I12: Delivered
A13: 46115 | B13: INV-0005 | C13: Walk-in Customer | D13: PVC Pipe 1in 6m | E13: 2 | H13: Cash | I13: Delivered
A14: 46115 | B14: INV-0006 | C14: Walk-in Customer | D14: Toothpaste 150g x12 | E14: 2 | H14: Cash | I14: Delivered
A15: 46115 | B15: INV-0006 | C15: Walk-in Customer | D15: Copper Wire 90m | E15: 1 | H15: Cash | I15: Delivered
A16: 46115 | B16: INV-0006 | C16: Walk-in Customer | D16: Cement 50kg | E16: 9 | H16: Cash | I16: Delivered
A17: 46116 | B17: INV-0007 | C17: Mehta Constructions | D17: Toothpaste 150g x12 | E17: 1 | H17: Bank | I17: Delivered
A18: 46116 | B18: INV-0007 | C18: Mehta Constructions | D18: Copper Wire 90m | E18: 1 | G18: 0.02 | H18: Bank | I18: Delivered
A19: 46116 | B19: INV-0007 | C19: Mehta Constructions | D19: Detergent 5kg | E19: 1 | H19: Bank | I19: Delivered
A20: 46116 | B20: INV-0008 | C20: Delhi Hardware Mart | D20: Basmati Rice 25kg | E20: 2 | G20: 0.05 | H20: UPI | I20: Delivered
A21: 46116 | B21: INV-0008 | C21: Delhi Hardware Mart | D21: A4 Paper Ream | E21: 6 | H21: UPI | I21: Delivered
A22: 46116 | B22: INV-0008 | C22: Delhi Hardware Mart | D22: Sugar 50kg | E22: 1 | H22: UPI | I22: Delivered
A23: 46118 | B23: INV-0009 | C23: Gupta Electricals | D23: Copper Wire 90m | E23: 1 | I23: Delivered
A24: 46118 | B24: INV-0009 | C24: Gupta Electricals | D24: A4 Paper Ream | E24: 5 | G24: 0.02 | I24: Delivered
A25: 46118 | B25: INV-0010 | C25: Mehta Constructions | D25: Basmati Rice 25kg | E25: 1 | G25: 0.05 | H25: UPI | I25: Delivered
A26: 46118 | B26: INV-0010 | C26: Mehta Constructions | D26: Copper Wire 90m | E26: 1 | H26: UPI | I26: Delivered
A27: 46118 | B27: INV-0011 | C27: Walk-in Customer | D27: Refined Oil 15L | E27: 1 | G27: 0.02 | H27: Cash | I27: Delivered
A28: 46118 | B28: INV-0011 | C28: Walk-in Customer | D28: Tea Premium 1kg | E28: 1 | G28: 0.02 | H28: Cash | I28: Delivered
A29: 46118 | B29: INV-0012 | C29: Walk-in Customer | D29: Refined Oil 15L | E29: 2 | H29: Cash | I29: Delivered
A30: 46118 | B30: INV-0012 | C30: Walk-in Customer | D30: LED Bulb 9W | E30: 19 | H30: Cash | I30: Delivered
A31: 46119 | B31: INV-0013 | C31: Walk-in Customer | D31: Sugar 50kg | E31: 1 | H31: Cash | I31: Delivered
A32: 46119 | B32: INV-0013 | C32: Walk-in Customer | D32: Refined Oil 15L | E32: 1 | G32: 0.05 | H32: Cash | I32: Delivered
A33: 46119 | B33: INV-0014 | C33: Delhi Hardware Mart | D33: Basmati Rice 25kg | E33: 1 | I33: Delivered
A34: 46119 | B34: INV-0014 | C34: Delhi Hardware Mart | D34: Refined Oil 15L | E34: 1 | I34: Delivered
A35: 46119 | B35: INV-0015 | C35: Delhi Hardware Mart | D35: Copper Wire 90m | E35: 1 | G35: 0.05 | H35: Bank | I35: Delivered
A36: 46119 | B36: INV-0016 | C36: Walk-in Customer | D36: LED Bulb 9W | E36: 14 | G36: 0.02 | H36: Cash | I36: Delivered
A37: 46119 | B37: INV-0016 | C37: Walk-in Customer | D37: Ceiling Fan 1200mm | E37: 1 | H37: Cash | I37: Delivered
A38: 46119 | B38: INV-0016 | C38: Walk-in Customer | D38: Sugar 50kg | E38: 1 | G38: 0.02 | H38: Cash | I38: Delivered
A39: 46120 | B39: INV-0017 | C39: Gupta Electricals | D39: Sugar 50kg | E39: 1 | I39: Delivered
A40: 46120 | B40: INV-0018 | C40: Gupta Electricals | D40: Sugar 50kg | E40: 1 | G40: 0.05 | I40: Delivered
...

Sheet Purchases
A1: 🛒 PURCHASES / GOODS RECEIVED (PROCURE) | U1: ◀ Home
A2: One line per item received. Stock, average cost, supplier payable and GST input credit update instantly.
A3: Blue / cream = type here | I3: ⚙ C engine: {=_xll.ST_PURCHASES(…)} fills I:S
A4: Date * | B4: Bill No * | C4: Supplier * | D4: Item * | E4: Qty * | F4: Rate (₹) blank=std | G4: Disc % | H4: Paid Via (blank=Credit) | I4: Unit | J4: Rate Used (₹) | K4: Taxable (₹) | L4: GST % | M4: CGST (₹) | N4: SGST (₹) | O4: IGST (₹) | P4: Bill Total (₹) | Q4: itemRow | R4: partyRow | S4: Paid Now (₹)
A5: 46113 | B5: B-0001 | C5: Bharat Electric Co | D5: Copper Wire 90m | E5: 13 | F5: 2517 | I5: {=_xll.ST_PURCHASES(IN_Items,IN_Parties,IN_Purchases,IN_Sales,IN_CashBook,IN_Adjust,IN_Settings)}
A6: 46113 | B6: B-0001 | C6: Bharat Electric Co | D6: Ceiling Fan 1200mm | E6: 21 | F6: 1650
A7: 46113 | B7: B-0002 | C7: FMCG Distributors | D7: Toothpaste 150g x12 | E7: 25 | F7: 885
A8: 46144 | B8: B-0003 | C8: Agro Foods Pvt Ltd | D8: Basmati Rice 25kg | E8: 29 | F8: 1690
A9: 46144 | B9: B-0003 | C9: Agro Foods Pvt Ltd | D9: Sugar 50kg | E9: 34 | F9: 2086
A10: 46144 | B10: B-0003 | C10: Agro Foods Pvt Ltd | D10: Refined Oil 15L | E10: 41 | F10: 1881
A11: 46144 | B11: B-0004 | C11: Bharat Electric Co | D11: LED Bulb 9W | E11: 311 | F11: 63 | H11: Bank
A12: 46144 | B12: B-0004 | C12: Bharat Electric Co | D12: Copper Wire 90m | E12: 13 | F12: 2427 | H12: Bank
A13: 46144 | B13: B-0004 | C13: Bharat Electric Co | D13: Ceiling Fan 1200mm | E13: 13 | F13: 1639 | H13: Bank
A14: 46144 | B14: B-0005 | C14: FMCG Distributors | D14: Tea Premium 1kg | E14: 78 | F14: 382
A15: 46144 | B15: B-0005 | C15: FMCG Distributors | D15: Detergent 5kg | E15: 47 | F15: 525
A16: 46144 | B16: B-0006 | C16: National Hardware Supply | D16: PVC Pipe 1in 6m | E16: 152 | F16: 207
A17: 46144 | B17: B-0006 | C17: National Hardware Supply | D17: Cement 50kg | E17: 111 | F17: 342
A18: 46175 | B18: B-0007 | C18: Bharat Electric Co | D18: LED Bulb 9W | E18: 204 | F18: 64
A19: 46175 | B19: B-0007 | C19: Bharat Electric Co | D19: Copper Wire 90m | E19: 17 | F19: 2490
A20: 46175 | B20: B-0007 | C20: Bharat Electric Co | D20: Ceiling Fan 1200mm | E20: 12 | F20: 1625
A21: 46175 | B21: B-0008 | C21: FMCG Distributors | D21: Detergent 5kg | E21: 31 | F21: 515
A22: 46175 | B22: B-0008 | C22: FMCG Distributors | D22: Toothpaste 150g x12 | E22: 30 | F22: 889
A23: 46205 | B23: B-0009 | C23: Agro Foods Pvt Ltd | D23: Basmati Rice 25kg | E23: 39 | F23: 1687 | H23: Bank
A24: 46205 | B24: B-0009 | C24: Agro Foods Pvt Ltd | D24: Sugar 50kg | E24: 25 | F24: 2067 | H24: Bank
A25: 46205 | B25: B-0009 | C25: Agro Foods Pvt Ltd | D25: Refined Oil 15L | E25: 27 | F25: 1935 | H25: Bank
A26: 46205 | B26: B-0010 | C26: Bharat Electric Co | D26: Copper Wire 90m | E26: 12 | F26: 2501
A27: 46205 | B27: B-0010 | C27: Bharat Electric Co | D27: Ceiling Fan 1200mm | E27: 16 | F27: 1687
A28: 46205 | B28: B-0011 | C28: FMCG Distributors | D28: Tea Premium 1kg | E28: 56 | F28: 379
A29: 46205 | B29: B-0011 | C29: FMCG Distributors | D29: Detergent 5kg | E29: 34 | F29: 513
A30: 46205 | B30: B-0012 | C30: National Hardware Supply | D30: PVC Pipe 1in 6m | E30: 142 | F30: 208
A31: 46205 | B31: B-0012 | C31: National Hardware Supply | D31: Cement 50kg | E31: 216 | F31: 340
A32: 46236 | B32: B-0013 | C32: Agro Foods Pvt Ltd | D32: Basmati Rice 25kg | E32: 25 | F32: 1646
A33: 46236 | B33: B-0014 | C33: Bharat Electric Co | D33: LED Bulb 9W | E33: 392 | F33: 61 | H33: Bank
A34: 46236 | B34: B-0014 | C34: Bharat Electric Co | D34: Copper Wire 90m | E34: 13 | F34: 2522 | H34: Bank
A35: 46236 | B35: B-0014 | C35: Bharat Electric Co | D35: Ceiling Fan 1200mm | E35: 16 | F35: 1653 | H35: Bank
A36: 46236 | B36: B-0015 | C36: FMCG Distributors | D36: Toothpaste 150g x12 | E36: 37 | F36: 904
A37: 46236 | B37: B-0016 | C37: National Hardware Supply | D37: PVC Pipe 1in 6m | E37: 100 | F37: 214
A38: 46267 | B38: B-0017 | C38: Agro Foods Pvt Ltd | D38: Sugar 50kg | E38: 26 | F38: 2081
A39: 46267 | B39: B-0017 | C39: Agro Foods Pvt Ltd | D39: Refined Oil 15L | E39: 29 | F39: 1910
A40: 46267 | B40: B-0018 | C40: Bharat Electric Co | D40: LED Bulb 9W | E40: 253 | F40: 64
...

Sheet CashBook
A1: 💰 CASH & BANK BOOK (FINANCE) | M1: ◀ Home
A2: Customer receipts, supplier payments, expenses, owner capital/drawings and transfers between accounts.
A3: Blue / cream = type here | I3: ⚙ C engine: {=_xll.ST_CASHBOOK(…)} fills I:K
A4: Date * | B4: Voucher No | C4: Type * | D4: Party (Receipt/Payment) | E4: Expense / Income Head | F4: Account * | G4: Amount (₹) * | H4: Reference / Notes | I4: Money In (₹) | J4: Money Out (₹) | K4: Check
A5: 46117 | B5: V-0001 | C5: Expense | E5: Rent | F5: Bank | G5: 18000 | I5: {=_xll.ST_CASHBOOK(IN_Items,IN_Parties,IN_Purchases,IN_Sales,IN_CashBook,IN_Adjust,IN_Settings)}
A6: 46117 | B6: V-0002 | C6: Expense | E6: Salary | F6: Bank | G6: 26000
A7: 46117 | B7: V-0003 | C7: Expense | E7: Electricity | F7: UPI | G7: 4417
A8: 46117 | B8: V-0004 | C8: Expense | E8: Transport / Freight | F8: Cash | G8: 8568
A9: 46117 | B9: V-0005 | C9: Expense | E9: Telephone / Internet | F9: UPI | G9: 1199
A10: 46122 | B10: V-0006 | C10: Receipt | D10: Sharma Kirana Store | F10: Bank | G10: 16500 | H10: NEFT/UPI
A11: 46122 | B11: V-0007 | C11: Receipt | D11: Gupta Electricals | F11: Bank | G11: 6600 | H11: NEFT/UPI
A12: 46122 | B12: V-0008 | C12: Receipt | D12: Delhi Hardware Mart | F12: UPI | G12: 3000 | H12: NEFT/UPI
A13: 46122 | B13: V-0009 | C13: Receipt | D13: Mehta Constructions | F13: Bank | G13: 6900 | H13: NEFT/UPI
A14: 46122 | B14: V-0010 | C14: Receipt | D14: FMCG Distributors | F14: UPI | G14: 700 | H14: NEFT/UPI
A15: 46122 | B15: V-0011 | C15: Payment | D15: Agro Foods Pvt Ltd | F15: Bank | G15: 20000 | H15: RTGS
A16: 46122 | B16: V-0012 | C16: Payment | D16: Bharat Electric Co | F16: Bank | G16: 54000 | H16: RTGS
A17: 46122 | B17: V-0013 | C17: Payment | D17: FMCG Distributors | F17: Bank | G17: 17000 | H17: RTGS
A18: 46137 | B18: V-0014 | C18: Receipt | D18: Sharma Kirana Store | F18: UPI | G18: 18300 | H18: NEFT/UPI
A19: 46137 | B19: V-0015 | C19: Receipt | D19: Gupta Electricals | F19: Bank | G19: 17900 | H19: NEFT/UPI
A20: 46137 | B20: V-0016 | C20: Receipt | D20: Delhi Hardware Mart | F20: Bank | G20: 7300 | H20: NEFT/UPI
A21: 46137 | B21: V-0017 | C21: Receipt | D21: Mehta Constructions | F21: Bank | G21: 19500 | H21: NEFT/UPI
... A25: 46137 | B25: V-0021 | C25: Payment | D25: FMCG Distributors | F25: Bank | G25: 4000 | H25: RTGS
A26: 46138 | B26: V-0022 | C26: Transfer Out | F26: Cash | G26: 145000 | H26: Cash deposited to Bank
A27: 46138 | B27: V-0022 | C27: Transfer In | F27: Bank | G27: 145000 | H27: Cash deposited to Bank
A28: 46138 | B28: V-0023 | C28: Transfer Out | F28: UPI | G28: 29000 | H28: UPI deposited to Bank
A29: 46138 | B29: V-0023 | C29: Transfer In | F29: Bank | G29: 29000 | H29: UPI deposited to Bank
A30: 46147 | B30: V-0024 | C30: Expense | E30: Rent | F30: Bank | G30: 18000
A31: 46147 | B31: V-0025 | C31: Expense | E31: Salary | F31: Bank | G31: 26000
A32: 46147 | B32: V-0026 | C32: Expense | E32: Electricity | F32: UPI | G32: 5088
A33: 46147 | B33: V-0027 | C33: Expense | E33: Transport / Freight | F33: Cash | G33: 7723
A34: 46147 | B34: V-0028 | C34: Expense | E34: Telephone / Internet | F34: UPI | G34: 1199
A35: 46152 | B35: V-0029 | C35: Receipt | D35: Sharma Kirana Store | F35: Bank | G35: 19200 | H35: NEFT/UPI
A36: 46152 | B36: V-0030 | C36: Receipt | D36: Gupta Electricals | F36: Bank | G36: 9900 | H36: NEFT/UPI
A37: 46152 | B37: V-0031 | C37: Receipt | D37: Delhi Hardware Mart | F37: Bank | G37: 20200 | H37: NEFT/UPI
A38: 46152 | B38: V-0032 | C38: Receipt | D38: Mehta Constructions | F38: UPI | G38: 3200 | H38: NEFT/UPI
A39: 46152 | B39: V-0033 | C39: Receipt | D39: FMCG Distributors | F39: UPI | G39: 11300 | H39: NEFT/UPI
A40: 46152 | B40: V-0034 | C40: Payment | D40: Agro Foods Pvt Ltd | F40: Bank | G40: 144000 | H40: RTGS
A41: 46152 | B41: V-0035 | C41: Payment | D41: Bharat Electric Co | F41: Bank | G41: 6000 | H41: RTGS
A42: 46152 | B42: V-0036 | C42: Payment | D42: FMCG Distributors | F42: Bank | G42: 40000 | H42: RTGS
A43: 46152 | B43: V-0037 | C43: Payment | D43: National Hardware Supply | F43: Bank | G43: 54000 | H43: RTGS
...

Sheet Items
A1: 📦 ITEM MASTER & LIVE STOCK | AB1: ◀ Home
A2: One row per product. Stock, cost, value and reorder alerts update automatically from Purchases, Sales and Adjustments.
A3: Blue / cream = type here | L3: ⚙ C engine: {=_xll.ST_ITEMS(…)} fills L:Z
A4: Item Name * | B4: SKU / Barcode | C4: Category | D4: Unit | E4: HSN | F4: GST % | G4: Std Purchase Rate (₹) | H4: Std Sale Rate (₹) | I4: Reorder Level | J4: Opening Qty | K4: Opening Rate (₹) | L4: Purchased Qty | M4: Sold Qty | N4: Adjust Qty | O4: Closing Stock | P4: Avg Cost (₹) | Q4: Stock Value (₹) | R4: Status | S4: Margin % | T4: Suggested Order Qty | U4: Sales Value (₹) | V4: Gross Profit (₹) | W4: Last Sold | X4: Days Since Sale | Y4: Days of Cover | Z4: rank key
A5: Basmati Rice 25kg | B5: 8901001 | C5: Grocery | D5: Bag | E5: 1006 | F5: 0.05 | G5: 1650 | H5: 2106 | I5: 10 | J5: 40 | K5: 1620 | L5: {=_xll.ST_ITEMS(IN_Items,IN_Parties,IN_Purchases,IN_Sales,IN_CashBook,IN_Adjust,IN_Settings)}
A6: Sugar 50kg | B6: 8901002 | C6: Grocery | D6: Bag | E6: 1701 | F6: 0.05 | G6: 2050 | H6: 2462 | I6: 8 | J6: 25 | K6: 2000
A7: Refined Oil 15L | B7: 8901003 | C7: Grocery | D7: Box | E7: 1512 | F7: 0.05 | G7: 1880 | H7: 2290 | I7: 10 | J7: 30 | K7: 1850
A8: Tea Premium 1kg | B8: 8901004 | C8: FMCG | D8: Pack | E8: 0902 | F8: 0.05 | G8: 380 | H8: 508 | I8: 20 | J8: 60 | K8: 375
A9: Detergent 5kg | B9: 8901005 | C9: FMCG | D9: Pack | E9: 3402 | F9: 0.18 | G9: 520 | H9: 691 | I9: 15 | J9: 50 | K9: 510
A10: Toothpaste 150g x12 | B10: 8901006 | C10: FMCG | D10: Box | E10: 3306 | F10: 0.05 | G10: 900 | H10: 1166 | I10: 10 | J10: 25 | K10: 880
A11: LED Bulb 9W | B11: 8901007 | C11: Electrical | D11: Pcs | E11: 8539 | F11: 0.18 | G11: 62 | H11: 107 | I11: 100 | J11: 300 | K11: 60
A12: Copper Wire 90m | B12: 8901008 | C12: Electrical | D12: Pcs | E12: 8544 | F12: 0.18 | G12: 2450 | H12: 3132 | I12: 5 | J12: 12 | K12: 2400
A13: PVC Pipe 1in 6m | B13: 8901009 | C13: Hardware | D13: Pcs | E13: 3917 | F13: 0.18 | G13: 210 | H13: 297 | I13: 40 | J13: 120 | K13: 205
A14: Cement 50kg | B14: 8901010 | C14: Hardware | D14: Bag | E14: 2523 | F14: 0.18 | G14: 340 | H14: 427 | I14: 50 | J14: 200 | K14: 335
A15: A4 Paper Ream | B15: 8901011 | C15: Stationery | D15: Pack | E15: 4802 | F15: 0.12 | G15: 245 | H15: 335 | I15: 30 | J15: 80 | K15: 240
A16: Ceiling Fan 1200mm | B16: 8901012 | C16: Electrical | D16: Pcs | E16: 8414 | F16: 0.18 | G16: 1650 | H16: 2322 | I16: 5 | J16: 4 | K16: 1600

Sheet Parties
A1: 👥 CUSTOMERS & SUPPLIERS (PARTY LEDGER) | U1: ◀ Home
A2: Balance > 0 means the party owes you (receivable); < 0 means you owe them (payable).
A3: Blue / cream = type here | J3: ⚙ C engine: {=_xll.ST_PARTIES(…)} fills J:S
A4: Party Name * | B4: Type | C4: Phone | D4: GSTIN | E4: State | F4: Address | G4: Credit Limit (₹) | H4: Credit Days | I4: Opening Bal (₹) +recv / -pay | J4: Credit Sales (₹) | K4: Received (₹) | L4: Credit Purchases (₹) | M4: Paid (₹) | N4: Balance (₹) | O4: Position | P4: Last Sale | Q4: Last Receipt | R4: Days Unpaid | S4: Alert
A5: Sharma Kirana Store | B5: Customer | C5: 9810000001 | D5: 08AAAPS1111A1Z1 | E5: Rajasthan | F5: Jaipur | G5: 50000 | H5: 15 | I5: 12000 | J5: {=_xll.ST_PARTIES(IN_Items,IN_Parties,IN_Purchases,IN_Sales,IN_CashBook,IN_Adjust,IN_Settings)}
A6: Gupta Electricals | B6: Customer | C6: 9810000002 | D6: 08AAAPG2222B1Z2 | E6: Rajasthan | F6: Ajmer | G6: 80000 | H6: 30 | I6: 0
A7: Delhi Hardware Mart | B7: Customer | C7: 9810000003 | D7: 07AAAPD3333C1Z3 | E7: Delhi | F7: Karol Bagh, Delhi | G7: 100000 | H7: 30 | I7: 0
A8: Walk-in Customer | B8: Customer | E8: Rajasthan | G8: 0 | H8: 0 | I8: 0
A9: Mehta Constructions | B9: Customer | C9: 9810000005 | D9: 08AAAPM5555E1Z5 | E9: Rajasthan | F9: Jodhpur | G9: 60000 | H9: 21 | I9: 8000
A10: Agro Foods Pvt Ltd | B10: Supplier | C10: 9810000006 | D10: 08AABCA6666F1Z6 | E10: Rajasthan | F10: Kota | G10: 0 | H10: 30 | I10: -25000
A11: Bharat Electric Co | B11: Supplier | C11: 9810000007 | D11: 27AABCB7777G1Z7 | E11: Maharashtra | F11: Mumbai | G11: 0 | H11: 45 | I11: 0
A12: National Hardware Supply | B12: Supplier | C12: 9810000008 | D12: 08AABCN8888H1Z8 | E12: Rajasthan | F12: Jaipur | G12: 0 | H12: 30 | I12: 0
A13: FMCG Distributors | B13: Both | C13: 9810000009 | D13: 08AABCF9999J1Z9 | E13: Rajasthan | F13: Jaipur | G13: 40000 | H13: 15 | I13: 0

Sheet Adjustments
A1: 🔧 STOCK ADJUSTMENTS | I1: ◀ Home
A2: Damage, expiry, physical-count corrections, returns. Negative qty reduces stock and is booked as a loss.
A3: Blue / cream = type here | F3: ⚙ C engine: {=_xll.ST_ADJUST(…)} fills F:G
A4: Date * | B4: Item * | C4: Qty (+in / -out) * | D4: Reason * | E4: Notes | F4: Avg Cost (₹) | G4: Value Impact (₹)
A5: 46162 | B5: Refined Oil 15L | C5: -2 | D5: Damage | E5: Leaking tins | F5: {=_xll.ST_ADJUST(IN_Items,IN_Parties,IN_Purchases,IN_Sales,IN_CashBook,IN_Adjust,IN_Settings)}
A6: 46205 | B6: LED Bulb 9W | C6: -6 | D6: Count Correction | E6: Physical count
A7: 46275 | B7: Basmati Rice 25kg | C7: 1 | D7: Sales Return | E7: Returned by Sharma Kirana

Sheet Invoice
A1: =CoName
A2: =CoAddr&" · "&CoPhone
A3: ="GSTIN: "&CoGSTIN&" · State: "&HomeState | M3: ◀ Home
A5: TAX INVOICE / DELIVERY CHALLAN
B7: Invoice No ▶ (type to reprint) | C7: =IF(COUNTA(Sales!$B$5:$B$20004)=0,"",INDEX(Sales!$B$5:$B$20004,COUNTA(Sales!$B$5:$B$20004))) | G7: Bill To | H7: =IFERROR(INDEX(Sales!$C$5:$C$20004,MATCH($C$7,Sales!$B$5:$B$20004,0)),"")
B8: Invoice Date | C8: =IFERROR(INDEX(Sales!$A$5:$A$20004,MATCH($C$7,Sales!$B$5:$B$20004,0)),"") | G8: GSTIN | H8: =IFERROR(INDEX(Parties!$D$5:$D$1004,MATCH($H$7,Parties!$A$5:$A$1004,0))&"","")
B9: Payment | C9: =IFERROR(IF(INDEX(Sales!$H$5:$H$20004,MATCH($C$7,Sales!$B$5:$B$20004,0))="","Credit",INDEX(Sales!$H$5:$H$20004,MATCH($C$7,Sales!$B$5:$B$20004,0))),"") | G9: State | H9: =IFERROR(INDEX(Parties!$E$5:$E$1004,MATCH($H$7,Parties!$A$5:$A$1004,0))&"","")
G10: Address | H10: =IFERROR(INDEX(Parties!$F$5:$F$1004,MATCH($H$7,Parties!$A$5:$A$1004,0))&"","")
A12: # | B12: Item | C12: HSN | D12: Qty | E12: Unit | F12: Rate (₹) | G12: Disc % | H12: Taxable (₹) | I12: GST % | J12: Tax (₹) | K12: Amount (₹)
A13: =IF(IFERROR(INDEX(Sales!$B$5:$B$20004,(MATCH($C$7,Sales!$B$5:$B$20004,0)+0))=$C$7,FALSE),1,"") | B13: =IF($A13="","",INDEX(Sales!$D$5:$D$20004,(MATCH($C$7,Sales!$B$5:$B$20004,0)+0))) | C13: =IF($A13="","",IFERROR(INDEX(Items!$E$5:$E$2004,INDEX(Sales!$U$5:$U$20004,(MATCH($C$7,Sales!$B$5:$B$20004,0)+0)))&"","")) | D13: =IF($A13="","",INDEX(Sales!$E$5:$E$20004,(MATCH($C$7,Sales!$B$5:$B$20004,0)+0))) | E13: =IF($A13="","",INDEX(Sales!$J$5:$J$20004,(MATCH($C$7,Sales!$B$5:$B$20004,0)+0))) | F13: =IF($A13="","",INDEX(Sales!$K$5:$K$20004,(MATCH($C$7,Sales!$B$5:$B$20004,0)+0))) | G13: =IF($A13="","",N(INDEX(Sales!$G$5:$G$20004,(MATCH($C$7,Sales!$B$5:$B$20004,0)+0)))) | H13: =IF($A13="","",INDEX(Sales!$L$5:$L$20004,(MATCH($C$7,Sales!$B$5:$B$20004,0)+0))) | I13: =IF($A13="","",INDEX(Sales!$M$5:$M$20004,(MATCH($C$7,Sales!$B$5:$B$20004,0)+0))) | J13: =IF($A13="","",INDEX(Sales!$N$5:$N$20004,(MATCH($C$7,Sales!$B$5:$B$20004,0)+0))+INDEX(Sales!$O$5:$O$20004,(MATCH($C$7,Sales!$B$5:$B$20004,0)+0))+INDEX(Sales!$P$5:$P$20004,(MATCH($C$7,Sales!$B$5:$B$20004,0)+0))) | K13: =IF($A13="","",INDEX(Sales!$Q$5:$Q$20004,(MATCH($C$7,Sales!$B$5:$B$20004,0)+0)))
A14: =IF(IFERROR(INDEX(Sales!$B$5:$B$20004,(MATCH($C$7,Sales!$B$5:$B$20004,0)+1))=$C$7,FALSE),2,"") | B14: =IF($A14="","",INDEX(Sales!$D$5:$D$20004,(MATCH($C$7,Sales!$B$5:$B$20004,0)+1))) | C14: =IF($A14="","",IFERROR(INDEX(Items!$E$5:$E$2004,INDEX(Sales!$U$5:$U$20004,(MATCH($C$7,Sales!$B$5:$B$20004,0)+1)))&"","")) | D14: =IF($A14="","",INDEX(Sales!$E$5:$E$20004,(MATCH($C$7,Sales!$B$5:$B$20004,0)+1))) | E14: =IF($A14="","",INDEX(Sales!$J$5:$J$20004,(MATCH($C$7,Sales!$B$5:$B$20004,0)+1))) | F14: =IF($A14="","",INDEX(Sales!$K$5:$K$20004,(MATCH($C$7,Sales!$B$5:$B$20004,0)+1))) | G14: =IF($A14="","",N(INDEX(Sales!$G$5:$G$20004,(MATCH($C$7,Sales!$B$5:$B$20004,0)+1)))) | H14: =IF($A14="","",INDEX(Sales!$L$5:$L$20004,(MATCH($C$7,Sales!$B$5:$B$20004,0)+1))) | I14: =IF($A14="","",INDEX(Sales!$M$5:$M$20004,(MATCH($C$7,Sales!$B$5:$B$20004,0)+1))) | J14: =IF($A14="","",INDEX(Sales!$N$5:$N$20004,(MATCH($C$7,Sales!$B$5:$B$20004,0)+1))+INDEX(Sales!$O$5:$O$20004,(MATCH($C$7,Sales!$B$5:$B$20004,0)+1))+INDEX(Sales!$P$5:$P$20004,(MATCH($C$7,Sales!$B$5:$B$20004,0)+1))) | K14: =IF($A14="","",INDEX(Sales!$Q$5:$Q$20004,(MATCH($C$7,Sales!$B$5:$B$20004,0)+1)))
A15: =IF(IFERROR(INDEX(Sales!$B$5:$B$20004,(MATCH($C$7,Sales!$B$5:$B$20004,0)+2))=$C$7,FALSE),3,"") | B15: =IF($A15="","",INDEX(Sales!$D$5:$D$20004,(MATCH($C$7,Sales!$B$5:$B$20004,0)+2))) | C15: =IF($A15="","",IFERROR(INDEX(Items!$E$5:$E$2004,INDEX(Sales!$U$5:$U$20004,(MATCH($C$7,Sales!$B$5:$B$20004,0)+2)))&"","")) | D15: =IF($A15="","",INDEX(Sales!$E$5:$E$20004,(MATCH($C$7,Sales!$B$5:$B$20004,0)+2))) | E15: =IF($A15="","",INDEX(Sales!$J$5:$J$20004,(MATCH($C$7,Sales!$B$5:$B$20004,0)+2))) | F15: =IF($A15="","",INDEX(Sales!$K$5:$K$20004,(MATCH($C$7,Sales!$B$5:$B$20004,0)+2))) | G15: =IF($A15="","",N(INDEX(Sales!$G$5:$G$20004,(MATCH($C$7,Sales!$B$5:$B$20004,0)+2)))) | H15: =IF($A15="","",INDEX(Sales!$L$5:$L$20004,(MATCH($C$7,Sales!$B$5:$B$20004,0)+2))) | I15: =IF($A15="","",INDEX(Sales!$M$5:$M$20004,(MATCH($C$7,Sales!$B$5:$B$20004,0)+2))) | J15: =IF($A15="","",INDEX(Sales!$N$5:$N$20004,(MATCH($C$7,Sales!$B$5:$B$20004,0)+2))+INDEX(Sales!$O$5:$O$20004,(MATCH($C$7,Sales!$B$5:$B$20004,0)+2))+INDEX(Sales!$P$5:$P$20004,(MATCH($C$7,Sales!$B$5:$B$20004,0)+2))) | K15: =IF($A15="","",INDEX(Sales!$Q$5:$Q$20004,(MATCH($C$7,Sales!$B$5:$B$20004,0)+2)))
A16: =IF(IFERROR(INDEX(Sales!$B$5:$B$20004,(MATCH($C$7,Sales!$B$5:$B$20004,0)+3))=$C$7,FALSE),4,"") | B16: =IF($A16="","",INDEX(Sales!$D$5:$D$20004,(MATCH($C$7,Sales!$B$5:$B$20004,0)+3))) | C16: =IF($A16="","",IFERROR(INDEX(Items!$E$5:$E$2004,INDEX(Sales!$U$5:$U$20004,(MATCH($C$7,Sales!$B$5:$B$20004,0)+3)))&"","")) | D16: =IF($A16="","",INDEX(Sales!$E$5:$E$20004,(MATCH($C$7,Sales!$B$5:$B$20004,0)+3))) | E16: =IF($A16="","",INDEX(Sales!$J$5:$J$20004,(MATCH($C$7,Sales!$B$5:$B$20004,0)+3))) | F16: =IF($A16="","",INDEX(Sales!$K$5:$K$20004,(MATCH($C$7,Sales!$B$5:$B$20004,0)+3))) | G16: =IF($A16="","",N(INDEX(Sales!$G$5:$G$20004,(MATCH($C$7,Sales!$B$5:$B$20004,0)+3)))) | H16: =IF($A16="","",INDEX(Sales!$L$5:$L$20004,(MATCH($C$7,Sales!$B$5:$B$20004,0)+3))) | I16: =IF($A16="","",INDEX(Sales!$M$5:$M$20004,(MATCH($C$7,Sales!$B$5:$B$20004,0)+3))) | J16: =IF($A16="","",INDEX(Sales!$N$5:$N$20004,(MATCH($C$7,Sales!$B$5:$B$20004,0)+3))+INDEX(Sales!$O$5:$O$20004,(MATCH($C$7,Sales!$B$5:$B$20004,0)+3))+INDEX(Sales!$P$5:$P$20004,(MATCH($C$7,Sales!$B$5:$B$20004,0)+3))) | K16: =IF($A16="","",INDEX(Sales!$Q$5:$Q$20004,(MATCH($C$7,Sales!$B$5:$B$20004,0)+3)))
A17: =IF(IFERROR(INDEX(Sales!$B$5:$B$20004,(MATCH($C$7,Sales!$B$5:$B$20004,0)+4))=$C$7,FALSE),5,"") | B17: =IF($A17="","",INDEX(Sales!$D$5:$D$20004,(MATCH($C$7,Sales!$B$5:$B$20004,0)+4))) | C17: =IF($A17="","",IFERROR(INDEX(Items!$E$5:$E$2004,INDEX(Sales!$U$5:$U$20004,(MATCH($C$7,Sales!$B$5:$B$20004,0)+4)))&"","")) | D17: =IF($A17="","",INDEX(Sales!$E$5:$E$20004,(MATCH($C$7,Sales!$B$5:$B$20004,0)+4))) | E17: =IF($A17="","",INDEX(Sales!$J$5:$J$20004,(MATCH($C$7,Sales!$B$5:$B$20004,0)+4))) | F17: =IF($A17="","",INDEX(Sales!$K$5:$K$20004,(MATCH($C$7,Sales!$B$5:$B$20004,0)+4))) | G17: =IF($A17="","",N(INDEX(Sales!$G$5:$G$20004,(MATCH($C$7,Sales!$B$5:$B$20004,0)+4)))) | H17: =IF($A17="","",INDEX(Sales!$L$5:$L$20004,(MATCH($C$7,Sales!$B$5:$B$20004,0)+4))) | I17: =IF($A17="","",INDEX(Sales!$M$5:$M$20004,(MATCH($C$7,Sales!$B$5:$B$20004,0)+4))) | J17: =IF($A17="","",INDEX(Sales!$N$5:$N$20004,(MATCH($C$7,Sales!$B$5:$B$20004,0)+4))+INDEX(Sales!$O$5:$O$20004,(MATCH($C$7,Sales!$B$5:$B$20004,0)+4))+INDEX(Sales!$P$5:$P$20004,(MATCH($C$7,Sales!$B$5:$B$20004,0)+4))) | K17: =IF($A17="","",INDEX(Sales!$Q$5:$Q$20004,(MATCH($C$7,Sales!$B$5:$B$20004,0)+4)))
A18: =IF(IFERROR(INDEX(Sales!$B$5:$B$20004,(MATCH($C$7,Sales!$B$5:$B$20004,0)+5))=$C$7,FALSE),6,"") | B18: =IF($A18="","",INDEX(Sales!$D$5:$D$20004,(MATCH($C$7,Sales!$B$5:$B$20004,0)+5))) | C18: =IF($A18="","",IFERROR(INDEX(Items!$E$5:$E$2004,INDEX(Sales!$U$5:$U$20004,(MATCH($C$7,Sales!$B$5:$B$20004,0)+5)))&"","")) | D18: =IF($A18="","",INDEX(Sales!$E$5:$E$20004,(MATCH($C$7,Sales!$B$5:$B$20004,0)+5))) | E18: =IF($A18="","",INDEX(Sales!$J$5:$J$20004,(MATCH($C$7,Sales!$B$5:$B$20004,0)+5))) | F18: =IF($A18="","",INDEX(Sales!$K$5:$K$20004,(MATCH($C$7,Sales!$B$5:$B$20004,0)+5))) | G18: =IF($A18="","",N(INDEX(Sales!$G$5:$G$20004,(MATCH($C$7,Sales!$B$5:$B$20004,0)+5)))) | H18: =IF($A18="","",INDEX(Sales!$L$5:$L$20004,(MATCH($C$7,Sales!$B$5:$B$20004,0)+5))) | I18: =IF($A18="","",INDEX(Sales!$M$5:$M$20004,(MATCH($C$7,Sales!$B$5:$B$20004,0)+5))) | J18: =IF($A18="","",INDEX(Sales!$N$5:$N$20004,(MATCH($C$7,Sales!$B$5:$B$20004,0)+5))+INDEX(Sales!$O$5:$O$20004,(MATCH($C$7,Sales!$B$5:$B$20004,0)+5))+INDEX(Sales!$P$5:$P$20004,(MATCH($C$7,Sales!$B$5:$B$20004,0)+5))) | K18: =IF($A18="","",INDEX(Sales!$Q$5:$Q$20004,(MATCH($C$7,Sales!$B$5:$B$20004,0)+5)))
A19: =IF(IFERROR(INDEX(Sales!$B$5:$B$20004,(MATCH($C$7,Sales!$B$5:$B$20004,0)+6))=$C$7,FALSE),7,"") | B19: =IF($A19="","",INDEX(Sales!$D$5:$D$20004,(MATCH($C$7,Sales!$B$5:$B$20004,0)+6))) | C19: =IF($A19="","",IFERROR(INDEX(Items!$E$5:$E$2004,INDEX(Sales!$U$5:$U$20004,(MATCH($C$7,Sales!$B$5:$B$20004,0)+6)))&"","")) | D19: =IF($A19="","",INDEX(Sales!$E$5:$E$20004,(MATCH($C$7,Sales!$B$5:$B$20004,0)+6))) | E19: =IF($A19="","",INDEX(Sales!$J$5:$J$20004,(MATCH($C$7,Sales!$B$5:$B$20004,0)+6))) | F19: =IF($A19="","",INDEX(Sales!$K$5:$K$20004,(MATCH($C$7,Sales!$B$5:$B$20004,0)+6))) | G19: =IF($A19="","",N(INDEX(Sales!$G$5:$G$20004,(MATCH($C$7,Sales!$B$5:$B$20004,0)+6)))) | H19: =IF($A19="","",INDEX(Sales!$L$5:$L$20004,(MATCH($C$7,Sales!$B$5:$B$20004,0)+6))) | I19: =IF($A19="","",INDEX(Sales!$M$5:$M$20004,(MATCH($C$7,Sales!$B$5:$B$20004,0)+6))) | J19: =IF($A19="","",INDEX(Sales!$N$5:$N$20004,(MATCH($C$7,Sales!$B$5:$B$20004,0)+6))+INDEX(Sales!$O$5:$O$20004,(MATCH($C$7,Sales!$B$5:$B$20004,0)+6))+INDEX(Sales!$P$5:$P$20004,(MATCH($C$7,Sales!$B$5:$B$20004,0)+6))) | K19: =IF($A19="","",INDEX(Sales!$Q$5:$Q$20004,(MATCH($C$7,Sales!$B$5:$B$20004,0)+6)))
A20: =IF(IFERROR(INDEX(Sales!$B$5:$B$20004,(MATCH($C$7,Sales!$B$5:$B$20004,0)+7))=$C$7,FALSE),8,"") | B20: =IF($A20="","",INDEX(Sales!$D$5:$D$20004,(MATCH($C$7,Sales!$B$5:$B$20004,0)+7))) | C20: =IF($A20="","",IFERROR(INDEX(Items!$E$5:$E$2004,INDEX(Sales!$U$5:$U$20004,(MATCH($C$7,Sales!$B$5:$B$20004,0)+7)))&"","")) | D20: =IF($A20="","",INDEX(Sales!$E$5:$E$20004,(MATCH($C$7,Sales!$B$5:$B$20004,0)+7))) | E20: =IF($A20="","",INDEX(Sales!$J$5:$J$20004,(MATCH($C$7,Sales!$B$5:$B$20004,0)+7))) | F20: =IF($A20="","",INDEX(Sales!$K$5:$K$20004,(MATCH($C$7,Sales!$B$5:$B$20004,0)+7))) | G20: =IF($A20="","",N(INDEX(Sales!$G$5:$G$20004,(MATCH($C$7,Sales!$B$5:$B$20004,0)+7)))) | H20: =IF($A20="","",INDEX(Sales!$L$5:$L$20004,(MATCH($C$7,Sales!$B$5:$B$20004,0)+7))) | I20: =IF($A20="","",INDEX(Sales!$M$5:$M$20004,(MATCH($C$7,Sales!$B$5:$B$20004,0)+7))) | J20: =IF($A20="","",INDEX(Sales!$N$5:$N$20004,(MATCH($C$7,Sales!$B$5:$B$20004,0)+7))+INDEX(Sales!$O$5:$O$20004,(MATCH($C$7,Sales!$B$5:$B$20004,0)+7))+INDEX(Sales!$P$5:$P$20004,(MATCH($C$7,Sales!$B$5:$B$20004,0)+7))) | K20: =IF($A20="","",INDEX(Sales!$Q$5:$Q$20004,(MATCH($C$7,Sales!$B$5:$B$20004,0)+7)))
A21: =IF(IFERROR(INDEX(Sales!$B$5:$B$20004,(MATCH($C$7,Sales!$B$5:$B$20004,0)+8))=$C$7,FALSE),9,"") | B21: =IF($A21="","",INDEX(Sales!$D$5:$D$20004,(MATCH($C$7,Sales!$B$5:$B$20004,0)+8))) | C21: =IF($A21="","",IFERROR(INDEX(Items!$E$5:$E$2004,INDEX(Sales!$U$5:$U$20004,(MATCH($C$7,Sales!$B$5:$B$20004,0)+8)))&"","")) | D21: =IF($A21="","",INDEX(Sales!$E$5:$E$20004,(MATCH($C$7,Sales!$B$5:$B$20004,0)+8))) | E21: =IF($A21="","",INDEX(Sales!$J$5:$J$20004,(MATCH($C$7,Sales!$B$5:$B$20004,0)+8))) | F21: =IF($A21="","",INDEX(Sales!$K$5:$K$20004,(MATCH($C$7,Sales!$B$5:$B$20004,0)+8))) | G21: =IF($A21="","",N(INDEX(Sales!$G$5:$G$20004,(MATCH($C$7,Sales!$B$5:$B$20004,0)+8)))) | H21: =IF($A21="","",INDEX(Sales!$L$5:$L$20004,(MATCH($C$7,Sales!$B$5:$B$20004,0)+8))) | I21: =IF($A21="","",INDEX(Sales!$M$5:$M$20004,(MATCH($C$7,Sales!$B$5:$B$20004,0)+8))) | J21: =IF($A21="","",INDEX(Sales!$N$5:$N$20004,(MATCH($C$7,Sales!$B$5:$B$20004,0)+8))+INDEX(Sales!$O$5:$O$20004,(MATCH($C$7,Sales!$B$5:$B$20004,0)+8))+INDEX(Sales!$P$5:$P$20004,(MATCH($C$7,Sales!$B$5:$B$20004,0)+8))) | K21: =IF($A21="","",INDEX(Sales!$Q$5:$Q$20004,(MATCH($C$7,Sales!$B$5:$B$20004,0)+8)))
A22: =IF(IFERROR(INDEX(Sales!$B$5:$B$20004,(MATCH($C$7,Sales!$B$5:$B$20004,0)+9))=$C$7,FALSE),10,"") | B22: =IF($A22="","",INDEX(Sales!$D$5:$D$20004,(MATCH($C$7,Sales!$B$5:$B$20004,0)+9))) | C22: =IF($A22="","",IFERROR(INDEX(Items!$E$5:$E$2004,INDEX(Sales!$U$5:$U$20004,(MATCH($C$7,Sales!$B$5:$B$20004,0)+9)))&"","")) | D22: =IF($A22="","",INDEX(Sales!$E$5:$E$20004,(MATCH($C$7,Sales!$B$5:$B$20004,0)+9))) | E22: =IF($A22="","",INDEX(Sales!$J$5:$J$20004,(MATCH($C$7,Sales!$B$5:$B$20004,0)+9))) | F22: =IF($A22="","",INDEX(Sales!$K$5:$K$20004,(MATCH($C$7,Sales!$B$5:$B$20004,0)+9))) | G22: =IF($A22="","",N(INDEX(Sales!$G$5:$G$20004,(MATCH($C$7,Sales!$B$5:$B$20004,0)+9)))) | H22: =IF($A22="","",INDEX(Sales!$L$5:$L$20004,(MATCH($C$7,Sales!$B$5:$B$20004,0)+9))) | I22: =IF($A22="","",INDEX(Sales!$M$5:$M$20004,(MATCH($C$7,Sales!$B$5:$B$20004,0)+9))) | J22: =IF($A22="","",INDEX(Sales!$N$5:$N$20004,(MATCH($C$7,Sales!$B$5:$B$20004,0)+9))+INDEX(Sales!$O$5:$O$20004,(MATCH($C$7,Sales!$B$5:$B$20004,0)+9))+INDEX(Sales!$P$5:$P$20004,(MATCH($C$7,Sales!$B$5:$B$20004,0)+9))) | K22: =IF($A22="","",INDEX(Sales!$Q$5:$Q$20004,(MATCH($C$7,Sales!$B$5:$B$20004,0)+9)))
A23: =IF(IFERROR(INDEX(Sales!$B$5:$B$20004,(MATCH($C$7,Sales!$B$5:$B$20004,0)+10))=$C$7,FALSE),11,"") | B23: =IF($A23="","",INDEX(Sales!$D$5:$D$20004,(MATCH($C$7,Sales!$B$5:$B$20004,0)+10))) | C23: =IF($A23="","",IFERROR(INDEX(Items!$E$5:$E$2004,INDEX(Sales!$U$5:$U$20004,(MATCH($C$7,Sales!$B$5:$B$20004,0)+10)))&"","")) | D23: =IF($A23="","",INDEX(Sales!$E$5:$E$20004,(MATCH($C$7,Sales!$B$5:$B$20004,0)+10))) | E23: =IF($A23="","",INDEX(Sales!$J$5:$J$20004,(MATCH($C$7,Sales!$B$5:$B$20004,0)+10))) | F23: =IF($A23="","",INDEX(Sales!$K$5:$K$20004,(MATCH($C$7,Sales!$B$5:$B$20004,0)+10))) | G23: =IF($A23="","",N(INDEX(Sales!$G$5:$G$20004,(MATCH($C$7,Sales!$B$5:$B$20004,0)+10)))) | H23: =IF($A23="","",INDEX(Sales!$L$5:$L$20004,(MATCH($C$7,Sales!$B$5:$B$20004,0)+10))) | I23: =IF($A23="","",INDEX(Sales!$M$5:$M$20004,(MATCH($C$7,Sales!$B$5:$B$20004,0)+10))) | J23: =IF($A23="","",INDEX(Sales!$N$5:$N$20004,(MATCH($C$7,Sales!$B$5:$B$20004,0)+10))+INDEX(Sales!$O$5:$O$20004,(MATCH($C$7,Sales!$B$5:$B$20004,0)+10))+INDEX(Sales!$P$5:$P$20004,(MATCH($C$7,Sales!$B$5:$B$20004,0)+10))) | K23: =IF($A23="","",INDEX(Sales!$Q$5:$Q$20004,(MATCH($C$7,Sales!$B$5:$B$20004,0)+10)))
A24: =IF(IFERROR(INDEX(Sales!$B$5:$B$20004,(MATCH($C$7,Sales!$B$5:$B$20004,0)+11))=$C$7,FALSE),12,"") | B24: =IF($A24="","",INDEX(Sales!$D$5:$D$20004,(MATCH($C$7,Sales!$B$5:$B$20004,0)+11))) | C24: =IF($A24="","",IFERROR(INDEX(Items!$E$5:$E$2004,INDEX(Sales!$U$5:$U$20004,(MATCH($C$7,Sales!$B$5:$B$20004,0)+11)))&"","")) | D24: =IF($A24="","",INDEX(Sales!$E$5:$E$20004,(MATCH($C$7,Sales!$B$5:$B$20004,0)+11))) | E24: =IF($A24="","",INDEX(Sales!$J$5:$J$20004,(MATCH($C$7,Sales!$B$5:$B$20004,0)+11))) | F24: =IF($A24="","",INDEX(Sales!$K$5:$K$20004,(MATCH($C$7,Sales!$B$5:$B$20004,0)+11))) | G24: =IF($A24="","",N(INDEX(Sales!$G$5:$G$20004,(MATCH($C$7,Sales!$B$5:$B$20004,0)+11)))) | H24: =IF($A24="","",INDEX(Sales!$L$5:$L$20004,(MATCH($C$7,Sales!$B$5:$B$20004,0)+11))) | I24: =IF($A24="","",INDEX(Sales!$M$5:$M$20004,(MATCH($C$7,Sales!$B$5:$B$20004,0)+11))) | J24: =IF($A24="","",INDEX(Sales!$N$5:$N$20004,(MATCH($C$7,Sales!$B$5:$B$20004,0)+11))+INDEX(Sales!$O$5:$O$20004,(MATCH($C$7,Sales!$B$5:$B$20004,0)+11))+INDEX(Sales!$P$5:$P$20004,(MATCH($C$7,Sales!$B$5:$B$20004,0)+11))) | K24: =IF($A24="","",INDEX(Sales!$Q$5:$Q$20004,(MATCH($C$7,Sales!$B$5:$B$20004,0)+11)))
A25: =IF(IFERROR(INDEX(Sales!$B$5:$B$20004,(MATCH($C$7,Sales!$B$5:$B$20004,0)+12))=$C$7,FALSE),13,"") | B25: =IF($A25="","",INDEX(Sales!$D$5:$D$20004,(MATCH($C$7,Sales!$B$5:$B$20004,0)+12))) | C25: =IF($A25="","",IFERROR(INDEX(Items!$E$5:$E$2004,INDEX(Sales!$U$5:$U$20004,(MATCH($C$7,Sales!$B$5:$B$20004,0)+12)))&"","")) | D25: =IF($A25="","",INDEX(Sales!$E$5:$E$20004,(MATCH($C$7,Sales!$B$5:$B$20004,0)+12))) | E25: =IF($A25="","",INDEX(Sales!$J$5:$J$20004,(MATCH($C$7,Sales!$B$5:$B$20004,0)+12))) | F25: =IF($A25="","",INDEX(Sales!$K$5:$K$20004,(MATCH($C$7,Sales!$B$5:$B$20004,0)+12))) | G25: =IF($A25="","",N(INDEX(Sales!$G$5:$G$20004,(MATCH($C$7,Sales!$B$5:$B$20004,0)+12)))) | H25: =IF($A25="","",INDEX(Sales!$L$5:$L$20004,(MATCH($C$7,Sales!$B$5:$B$20004,0)+12))) | I25: =IF($A25="","",INDEX(Sales!$M$5:$M$20004,(MATCH($C$7,Sales!$B$5:$B$20004,0)+12))) | J25: =IF($A25="","",INDEX(Sales!$N$5:$N$20004,(MATCH($C$7,Sales!$B$5:$B$20004,0)+12))+INDEX(Sales!$O$5:$O$20004,(MATCH($C$7,Sales!$B$5:$B$20004,0)+12))+INDEX(Sales!$P$5:$P$20004,(MATCH($C$7,Sales!$B$5:$B$20004,0)+12))) | K25: =IF($A25="","",INDEX(Sales!$Q$5:$Q$20004,(MATCH($C$7,Sales!$B$5:$B$20004,0)+12)))
A26: =IF(IFERROR(INDEX(Sales!$B$5:$B$20004,(MATCH($C$7,Sales!$B$5:$B$20004,0)+13))=$C$7,FALSE),14,"") | B26: =IF($A26="","",INDEX(Sales!$D$5:$D$20004,(MATCH($C$7,Sales!$B$5:$B$20004,0)+13))) | C26: =IF($A26="","",IFERROR(INDEX(Items!$E$5:$E$2004,INDEX(Sales!$U$5:$U$20004,(MATCH($C$7,Sales!$B$5:$B$20004,0)+13)))&"","")) | D26: =IF($A26="","",INDEX(Sales!$E$5:$E$20004,(MATCH($C$7,Sales!$B$5:$B$20004,0)+13))) | E26: =IF($A26="","",INDEX(Sales!$J$5:$J$20004,(MATCH($C$7,Sales!$B$5:$B$20004,0)+13))) | F26: =IF($A26="","",INDEX(Sales!$K$5:$K$20004,(MATCH($C$7,Sales!$B$5:$B$20004,0)+13))) | G26: =IF($A26="","",N(INDEX(Sales!$G$5:$G$20004,(MATCH($C$7,Sales!$B$5:$B$20004,0)+13)))) | H26: =IF($A26="","",INDEX(Sales!$L$5:$L$20004,(MATCH($C$7,Sales!$B$5:$B$20004,0)+13))) | I26: =IF($A26="","",INDEX(Sales!$M$5:$M$20004,(MATCH($C$7,Sales!$B$5:$B$20004,0)+13))) | J26: =IF($A26="","",INDEX(Sales!$N$5:$N$20004,(MATCH($C$7,Sales!$B$5:$B$20004,0)+13))+INDEX(Sales!$O$5:$O$20004,(MATCH($C$7,Sales!$B$5:$B$20004,0)+13))+INDEX(Sales!$P$5:$P$20004,(MATCH($C$7,Sales!$B$5:$B$20004,0)+13))) | K26: =IF($A26="","",INDEX(Sales!$Q$5:$Q$20004,(MATCH($C$7,Sales!$B$5:$B$20004,0)+13)))
A27: =IF(IFERROR(INDEX(Sales!$B$5:$B$20004,(MATCH($C$7,Sales!$B$5:$B$20004,0)+14))=$C$7,FALSE),15,"") | B27: =IF($A27="","",INDEX(Sales!$D$5:$D$20004,(MATCH($C$7,Sales!$B$5:$B$20004,0)+14))) | C27: =IF($A27="","",IFERROR(INDEX(Items!$E$5:$E$2004,INDEX(Sales!$U$5:$U$20004,(MATCH($C$7,Sales!$B$5:$B$20004,0)+14)))&"","")) | D27: =IF($A27="","",INDEX(Sales!$E$5:$E$20004,(MATCH($C$7,Sales!$B$5:$B$20004,0)+14))) | E27: =IF($A27="","",INDEX(Sales!$J$5:$J$20004,(MATCH($C$7,Sales!$B$5:$B$20004,0)+14))) | F27: =IF($A27="","",INDEX(Sales!$K$5:$K$20004,(MATCH($C$7,Sales!$B$5:$B$20004,0)+14))) | G27: =IF($A27="","",N(INDEX(Sales!$G$5:$G$20004,(MATCH($C$7,Sales!$B$5:$B$20004,0)+14)))) | H27: =IF($A27="","",INDEX(Sales!$L$5:$L$20004,(MATCH($C$7,Sales!$B$5:$B$20004,0)+14))) | I27: =IF($A27="","",INDEX(Sales!$M$5:$M$20004,(MATCH($C$7,Sales!$B$5:$B$20004,0)+14))) | J27: =IF($A27="","",INDEX(Sales!$N$5:$N$20004,(MATCH($C$7,Sales!$B$5:$B$20004,0)+14))+INDEX(Sales!$O$5:$O$20004,(MATCH($C$7,Sales!$B$5:$B$20004,0)+14))+INDEX(Sales!$P$5:$P$20004,(MATCH($C$7,Sales!$B$5:$B$20004,0)+14))) | K27: =IF($A27="","",INDEX(Sales!$Q$5:$Q$20004,(MATCH($C$7,Sales!$B$5:$B$20004,0)+14)))
A28: =IF(IFERROR(INDEX(Sales!$B$5:$B$20004,(MATCH($C$7,Sales!$B$5:$B$20004,0)+15))=$C$7,FALSE),16,"") | B28: =IF($A28="","",INDEX(Sales!$D$5:$D$20004,(MATCH($C$7,Sales!$B$5:$B$20004,0)+15))) | C28: =IF($A28="","",IFERROR(INDEX(Items!$E$5:$E$2004,INDEX(Sales!$U$5:$U$20004,(MATCH($C$7,Sales!$B$5:$B$20004,0)+15)))&"","")) | D28: =IF($A28="","",INDEX(Sales!$E$5:$E$20004,(MATCH($C$7,Sales!$B$5:$B$20004,0)+15))) | E28: =IF($A28="","",INDEX(Sales!$J$5:$J$20004,(MATCH($C$7,Sales!$B$5:$B$20004,0)+15))) | F28: =IF($A28="","",INDEX(Sales!$K$5:$K$20004,(MATCH($C$7,Sales!$B$5:$B$20004,0)+15))) | G28: =IF($A28="","",N(INDEX(Sales!$G$5:$G$20004,(MATCH($C$7,Sales!$B$5:$B$20004,0)+15)))) | H28: =IF($A28="","",INDEX(Sales!$L$5:$L$20004,(MATCH($C$7,Sales!$B$5:$B$20004,0)+15))) | I28: =IF($A28="","",INDEX(Sales!$M$5:$M$20004,(MATCH($C$7,Sales!$B$5:$B$20004,0)+15))) | J28: =IF($A28="","",INDEX(Sales!$N$5:$N$20004,(MATCH($C$7,Sales!$B$5:$B$20004,0)+15))+INDEX(Sales!$O$5:$O$20004,(MATCH($C$7,Sales!$B$5:$B$20004,0)+15))+INDEX(Sales!$P$5:$P$20004,(MATCH($C$7,Sales!$B$5:$B$20004,0)+15))) | K28: =IF($A28="","",INDEX(Sales!$Q$5:$Q$20004,(MATCH($C$7,Sales!$B$5:$B$20004,0)+15)))
A29: =IF(IFERROR(INDEX(Sales!$B$5:$B$20004,(MATCH($C$7,Sales!$B$5:$B$20004,0)+16))=$C$7,FALSE),17,"") | B29: =IF($A29="","",INDEX(Sales!$D$5:$D$20004,(MATCH($C$7,Sales!$B$5:$B$20004,0)+16))) | C29: =IF($A29="","",IFERROR(INDEX(Items!$E$5:$E$2004,INDEX(Sales!$U$5:$U$20004,(MATCH($C$7,Sales!$B$5:$B$20004,0)+16)))&"","")) | D29: =IF($A29="","",INDEX(Sales!$E$5:$E$20004,(MATCH($C$7,Sales!$B$5:$B$20004,0)+16))) | E29: =IF($A29="","",INDEX(Sales!$J$5:$J$20004,(MATCH($C$7,Sales!$B$5:$B$20004,0)+16))) | F29: =IF($A29="","",INDEX(Sales!$K$5:$K$20004,(MATCH($C$7,Sales!$B$5:$B$20004,0)+16))) | G29: =IF($A29="","",N(INDEX(Sales!$G$5:$G$20004,(MATCH($C$7,Sales!$B$5:$B$20004,0)+16)))) | H29: =IF($A29="","",INDEX(Sales!$L$5:$L$20004,(MATCH($C$7,Sales!$B$5:$B$20004,0)+16))) | I29: =IF($A29="","",INDEX(Sales!$M$5:$M$20004,(MATCH($C$7,Sales!$B$5:$B$20004,0)+16))) | J29: =IF($A29="","",INDEX(Sales!$N$5:$N$20004,(MATCH($C$7,Sales!$B$5:$B$20004,0)+16))+INDEX(Sales!$O$5:$O$20004,(MATCH($C$7,Sales!$B$5:$B$20004,0)+16))+INDEX(Sales!$P$5:$P$20004,(MATCH($C$7,Sales!$B$5:$B$20004,0)+16))) | K29: =IF($A29="","",INDEX(Sales!$Q$5:$Q$20004,(MATCH($C$7,Sales!$B$5:$B$20004,0)+16)))
A30: =IF(IFERROR(INDEX(Sales!$B$5:$B$20004,(MATCH($C$7,Sales!$B$5:$B$20004,0)+17))=$C$7,FALSE),18,"") | B30: =IF($A30="","",INDEX(Sales!$D$5:$D$20004,(MATCH($C$7,Sales!$B$5:$B$20004,0)+17))) | C30: =IF($A30="","",IFERROR(INDEX(Items!$E$5:$E$2004,INDEX(Sales!$U$5:$U$20004,(MATCH($C$7,Sales!$B$5:$B$20004,0)+17)))&"","")) | D30: =IF($A30="","",INDEX(Sales!$E$5:$E$20004,(MATCH($C$7,Sales!$B$5:$B$20004,0)+17))) | E30: =IF($A30="","",INDEX(Sales!$J$5:$J$20004,(MATCH($C$7,Sales!$B$5:$B$20004,0)+17))) | F30: =IF($A30="","",INDEX(Sales!$K$5:$K$20004,(MATCH($C$7,Sales!$B$5:$B$20004,0)+17))) | G30: =IF($A30="","",N(INDEX(Sales!$G$5:$G$20004,(MATCH($C$7,Sales!$B$5:$B$20004,0)+17)))) | H30: =IF($A30="","",INDEX(Sales!$L$5:$L$20004,(MATCH($C$7,Sales!$B$5:$B$20004,0)+17))) | I30: =IF($A30="","",INDEX(Sales!$M$5:$M$20004,(MATCH($C$7,Sales!$B$5:$B$20004,0)+17))) | J30: =IF($A30="","",INDEX(Sales!$N$5:$N$20004,(MATCH($C$7,Sales!$B$5:$B$20004,0)+17))+INDEX(Sales!$O$5:$O$20004,(MATCH($C$7,Sales!$B$5:$B$20004,0)+17))+INDEX(Sales!$P$5:$P$20004,(MATCH($C$7,Sales!$B$5:$B$20004,0)+17))) | K30: =IF($A30="","",INDEX(Sales!$Q$5:$Q$20004,(MATCH($C$7,Sales!$B$5:$B$20004,0)+17)))
A31: =IF(IFERROR(INDEX(Sales!$B$5:$B$20004,(MATCH($C$7,Sales!$B$5:$B$20004,0)+18))=$C$7,FALSE),19,"") | B31: =IF($A31="","",INDEX(Sales!$D$5:$D$20004,(MATCH($C$7,Sales!$B$5:$B$20004,0)+18))) | C31: =IF($A31="","",IFERROR(INDEX(Items!$E$5:$E$2004,INDEX(Sales!$U$5:$U$20004,(MATCH($C$7,Sales!$B$5:$B$20004,0)+18)))&"","")) | D31: =IF($A31="","",INDEX(Sales!$E$5:$E$20004,(MATCH($C$7,Sales!$B$5:$B$20004,0)+18))) | E31: =IF($A31="","",INDEX(Sales!$J$5:$J$20004,(MATCH($C$7,Sales!$B$5:$B$20004,0)+18))) | F31: =IF($A31="","",INDEX(Sales!$K$5:$K$20004,(MATCH($C$7,Sales!$B$5:$B$20004,0)+18))) | G31: =IF($A31="","",N(INDEX(Sales!$G$5:$G$20004,(MATCH($C$7,Sales!$B$5:$B$20004,0)+18)))) | H31: =IF($A31="","",INDEX(Sales!$L$5:$L$20004,(MATCH($C$7,Sales!$B$5:$B$20004,0)+18))) | I31: =IF($A31="","",INDEX(Sales!$M$5:$M$20004,(MATCH($C$7,Sales!$B$5:$B$20004,0)+18))) | J31: =IF($A31="","",INDEX(Sales!$N$5:$N$20004,(MATCH($C$7,Sales!$B$5:$B$20004,0)+18))+INDEX(Sales!$O$5:$O$20004,(MATCH($C$7,Sales!$B$5:$B$20004,0)+18))+INDEX(Sales!$P$5:$P$20004,(MATCH($C$7,Sales!$B$5:$B$20004,0)+18))) | K31: =IF($A31="","",INDEX(Sales!$Q$5:$Q$20004,(MATCH($C$7,Sales!$B$5:$B$20004,0)+18)))
A32: =IF(IFERROR(INDEX(Sales!$B$5:$B$20004,(MATCH($C$7,Sales!$B$5:$B$20004,0)+19))=$C$7,FALSE),20,"") | B32: =IF($A32="","",INDEX(Sales!$D$5:$D$20004,(MATCH($C$7,Sales!$B$5:$B$20004,0)+19))) | C32: =IF($A32="","",IFERROR(INDEX(Items!$E$5:$E$2004,INDEX(Sales!$U$5:$U$20004,(MATCH($C$7,Sales!$B$5:$B$20004,0)+19)))&"","")) | D32: =IF($A32="","",INDEX(Sales!$E$5:$E$20004,(MATCH($C$7,Sales!$B$5:$B$20004,0)+19))) | E32: =IF($A32="","",INDEX(Sales!$J$5:$J$20004,(MATCH($C$7,Sales!$B$5:$B$20004,0)+19))) | F32: =IF($A32="","",INDEX(Sales!$K$5:$K$20004,(MATCH($C$7,Sales!$B$5:$B$20004,0)+19))) | G32: =IF($A32="","",N(INDEX(Sales!$G$5:$G$20004,(MATCH($C$7,Sales!$B$5:$B$20004,0)+19)))) | H32: =IF($A32="","",INDEX(Sales!$L$5:$L$20004,(MATCH($C$7,Sales!$B$5:$B$20004,0)+19))) | I32: =IF($A32="","",INDEX(Sales!$M$5:$M$20004,(MATCH($C$7,Sales!$B$5:$B$20004,0)+19))) | J32: =IF($A32="","",INDEX(Sales!$N$5:$N$20004,(MATCH($C$7,Sales!$B$5:$B$20004,0)+19))+INDEX(Sales!$O$5:$O$20004,(MATCH($C$7,Sales!$B$5:$B$20004,0)+19))+INDEX(Sales!$P$5:$P$20004,(MATCH($C$7,Sales!$B$5:$B$20004,0)+19))) | K32: =IF($A32="","",INDEX(Sales!$Q$5:$Q$20004,(MATCH($C$7,Sales!$B$5:$B$20004,0)+19)))
B34: =IF(COUNTIF(A13:A32,">0")>=20,"⚠ More than 20 lines: split the invoice","") | H34: Taxable Value | K34: =SUMIFS(Sales!$L$5:$L$20004,Sales!$B$5:$B$20004,$C$7)
B35: ="Bank: "&CoBank | H35: CGST | K35: =SUMIFS(Sales!$N$5:$N$20004,Sales!$B$5:$B$20004,$C$7)
B36: Goods once sold will be taken back only as per store policy. | H36: SGST | K36: =SUMIFS(Sales!$O$5:$O$20004,Sales!$B$5:$B$20004,$C$7)
H37: IGST | K37: =SUMIFS(Sales!$P$5:$P$20004,Sales!$B$5:$B$20004,$C$7)
B38: Receiver's Signature | H38: Round Off | K38: =ROUND(SUM(K34:K37),0)-SUM(K34:K37)
H39: INVOICE TOTAL | K39: =SUM(K34:K38)
H41: ="For "&CoName
H43: Authorised Signatory

Sheet Reports
A1: 📊 REPORTS: MONTHLY P&L, GST, EXPENSES | N1: ◀ Home
A2: Financial-year view built from all registers. Nothing to type here.
A4: Month | B4: Sales (₹) | C4: COGS (₹) | D4: Gross Profit (₹) | E4: GP % | F4: Expenses (₹) | G4: Other Income (₹) | H4: Stock Loss/Gain (₹) | I4: Net Profit (₹) | J4: Purchases (₹) | K4: GST Output (₹) | L4: GST Input (₹) | M4: Net GST Payable (₹)
A5: =EDATE(FYStart,0) | B5: =SUMIFS(Sales!$L$5:$L$20004,Sales!$A$5:$A$20004,">="&$A5,Sales!$A$5:$A$20004,"<"&EDATE($A5,1)) | C5: =SUMIFS(Sales!$R$5:$R$20004,Sales!$A$5:$A$20004,">="&$A5,Sales!$A$5:$A$20004,"<"&EDATE($A5,1)) | D5: =B5-C5 | E5: =IF(B5=0,0,D5/B5) | F5: =SUMIFS(CashBook!$G$5:$G$20004,CashBook!$C$5:$C$20004,"Expense",CashBook!$A$5:$A$20004,">="&$A5,CashBook!$A$5:$A$20004,"<"&EDATE($A5,1)) | G5: =SUMIFS(CashBook!$G$5:$G$20004,CashBook!$C$5:$C$20004,"Other Income",CashBook!$A$5:$A$20004,">="&$A5,CashBook!$A$5:$A$20004,"<"&EDATE($A5,1)) | H5: =SUMIFS(Adjustments!$G$5:$G$2004,Adjustments!$A$5:$A$2004,">="&$A5,Adjustments!$A$5:$A$2004,"<"&EDATE($A5,1)) | I5: =D5-F5+G5+H5 | J5: =SUMIFS(Purchases!$K$5:$K$20004,Purchases!$A$5:$A$20004,">="&$A5,Purchases!$A$5:$A$20004,"<"&EDATE($A5,1)) | K5: =SUMIFS(Sales!$N$5:$N$20004,Sales!$A$5:$A$20004,">="&$A5,Sales!$A$5:$A$20004,"<"&EDATE($A5,1))+SUMIFS(Sales!$O$5:$O$20004,Sales!$A$5:$A$20004,">="&$A5,Sales!$A$5:$A$20004,"<"&EDATE($A5,1))+SUMIFS(Sales!$P$5:$P$20004,Sales!$A$5:$A$20004,">="&$A5,Sales!$A$5:$A$20004,"<"&EDATE($A5,1)) | L5: =SUMIFS(Purchases!$M$5:$M$20004,Purchases!$A$5:$A$20004,">="&$A5,Purchases!$A$5:$A$20004,"<"&EDATE($A5,1))+SUMIFS(Purchases!$N$5:$N$20004,Purchases!$A$5:$A$20004,">="&$A5,Purchases!$A$5:$A$20004,"<"&EDATE($A5,1))+SUMIFS(Purchases!$O$5:$O$20004,Purchases!$A$5:$A$20004,">="&$A5,Purchases!$A$5:$A$20004,"<"&EDATE($A5,1)) | M5: =K5-L5
A6: =EDATE(FYStart,1) | B6: =SUMIFS(Sales!$L$5:$L$20004,Sales!$A$5:$A$20004,">="&$A6,Sales!$A$5:$A$20004,"<"&EDATE($A6,1)) | C6: =SUMIFS(Sales!$R$5:$R$20004,Sales!$A$5:$A$20004,">="&$A6,Sales!$A$5:$A$20004,"<"&EDATE($A6,1)) | D6: =B6-C6 | E6: =IF(B6=0,0,D6/B6) | F6: =SUMIFS(CashBook!$G$5:$G$20004,CashBook!$C$5:$C$20004,"Expense",CashBook!$A$5:$A$20004,">="&$A6,CashBook!$A$5:$A$20004,"<"&EDATE($A6,1)) | G6: =SUMIFS(CashBook!$G$5:$G$20004,CashBook!$C$5:$C$20004,"Other Income",CashBook!$A$5:$A$20004,">="&$A6,CashBook!$A$5:$A$20004,"<"&EDATE($A6,1)) | H6: =SUMIFS(Adjustments!$G$5:$G$2004,Adjustments!$A$5:$A$2004,">="&$A6,Adjustments!$A$5:$A$2004,"<"&EDATE($A6,1)) | I6: =D6-F6+G6+H6 | J6: =SUMIFS(Purchases!$K$5:$K$20004,Purchases!$A$5:$A$20004,">="&$A6,Purchases!$A$5:$A$20004,"<"&EDATE($A6,1)) | K6: =SUMIFS(Sales!$N$5:$N$20004,Sales!$A$5:$A$20004,">="&$A6,Sales!$A$5:$A$20004,"<"&EDATE($A6,1))+SUMIFS(Sales!$O$5:$O$20004,Sales!$A$5:$A$20004,">="&$A6,Sales!$A$5:$A$20004,"<"&EDATE($A6,1))+SUMIFS(Sales!$P$5:$P$20004,Sales!$A$5:$A$20004,">="&$A6,Sales!$A$5:$A$20004,"<"&EDATE($A6,1)) | L6: =SUMIFS(Purchases!$M$5:$M$20004,Purchases!$A$5:$A$20004,">="&$A6,Purchases!$A$5:$A$20004,"<"&EDATE($A6,1))+SUMIFS(Purchases!$N$5:$N$20004,Purchases!$A$5:$A$20004,">="&$A6,Purchases!$A$5:$A$20004,"<"&EDATE($A6,1))+SUMIFS(Purchases!$O$5:$O$20004,Purchases!$A$5:$A$20004,">="&$A6,Purchases!$A$5:$A$20004,"<"&EDATE($A6,1)) | M6: =K6-L6
A7: =EDATE(FYStart,2) | B7: =SUMIFS(Sales!$L$5:$L$20004,Sales!$A$5:$A$20004,">="&$A7,Sales!$A$5:$A$20004,"<"&EDATE($A7,1)) | C7: =SUMIFS(Sales!$R$5:$R$20004,Sales!$A$5:$A$20004,">="&$A7,Sales!$A$5:$A$20004,"<"&EDATE($A7,1)) | D7: =B7-C7 | E7: =IF(B7=0,0,D7/B7) | F7: =SUMIFS(CashBook!$G$5:$G$20004,CashBook!$C$5:$C$20004,"Expense",CashBook!$A$5:$A$20004,">="&$A7,CashBook!$A$5:$A$20004,"<"&EDATE($A7,1)) | G7: =SUMIFS(CashBook!$G$5:$G$20004,CashBook!$C$5:$C$20004,"Other Income",CashBook!$A$5:$A$20004,">="&$A7,CashBook!$A$5:$A$20004,"<"&EDATE($A7,1)) | H7: =SUMIFS(Adjustments!$G$5:$G$2004,Adjustments!$A$5:$A$2004,">="&$A7,Adjustments!$A$5:$A$2004,"<"&EDATE($A7,1)) | I7: =D7-F7+G7+H7 | J7: =SUMIFS(Purchases!$K$5:$K$20004,Purchases!$A$5:$A$20004,">="&$A7,Purchases!$A$5:$A$20004,"<"&EDATE($A7,1)) | K7: =SUMIFS(Sales!$N$5:$N$20004,Sales!$A$5:$A$20004,">="&$A7,Sales!$A$5:$A$20004,"<"&EDATE($A7,1))+SUMIFS(Sales!$O$5:$O$20004,Sales!$A$5:$A$20004,">="&$A7,Sales!$A$5:$A$20004,"<"&EDATE($A7,1))+SUMIFS(Sales!$P$5:$P$20004,Sales!$A$5:$A$20004,">="&$A7,Sales!$A$5:$A$20004,"<"&EDATE($A7,1)) | L7: =SUMIFS(Purchases!$M$5:$M$20004,Purchases!$A$5:$A$20004,">="&$A7,Purchases!$A$5:$A$20004,"<"&EDATE($A7,1))+SUMIFS(Purchases!$N$5:$N$20004,Purchases!$A$5:$A$20004,">="&$A7,Purchases!$A$5:$A$20004,"<"&EDATE($A7,1))+SUMIFS(Purchases!$O$5:$O$20004,Purchases!$A$5:$A$20004,">="&$A7,Purchases!$A$5:$A$20004,"<"&EDATE($A7,1)) | M7: =K7-L7
